Workbook
Name A: #REF!
Name A: #REF!
Name A: #REF!
Name A: #REF!
Name A: #REF!
Name A: #REF!
Name HD: #REF!
Name HD: #REF!
Name HD: #REF!
Name HD: #REF!
Name HD: #REF!
Name HD: #REF!
Name HD: #REF!
Name 레시피: #REF!
Name 레시피: #REF!
Name 레시피: #REF!
Name 레시피: #REF!
Name 레시피: #REF!
Name 레시피: #REF!
Name 레시피: #REF!
Name 색상명: #REF!
Name 색상명: #REF!
Name 색상명: #REF!
Name 색상명: #REF!
Name 색상명: #REF!
Name 색상명: #REF!
Name 색상명: #REF!
Name 잉크명: #REF!
Name 잉크명: #REF!
Name 잉크명: #REF!
Name 잉크명: #REF!
Name 잉크명: #REF!
Name 잉크명: #REF!
Name 잉크명: #REF!

Sheet 사출계획
C2: 주간 사출 생산 계획
C5: 국내/ 스타비젼 | E5: SOUL BROWN | F5: JAZZ BLACK | G5: RHAPSODY | H5: LATIN | I5: SUZY G | J5: NELLY BROWN | K5: IRIS2 Sheer | L5: IRIS2 Veil | M5: IRIS2 Orange | N5: Ice gray | O5: ALICIA BROWN | P5: BLUE MOON | Q5: SUZY BROWN | R5: Astra Estelle Brown | S5: Astra Estelle Gray | T5: Astra Glitter | V5: 아이리스
E6: HALO BROWN | F6: HALO GRAY | G6: MOCHA BROWN | H6: CRYSTAL GRAY | I6: CHOCO BROWN | J6: 세라믹소울 | K6: 세라믹랩소디 | L6: 세라믹수지그레 | M6: 블루라이트 | N6: 세라믹라틴 | O6: 세라믹수지브라운 | P6: 세라믹째즈 | Q6: NOX GRAY | R6: DAWN NAVY | S6: ROSY BROWN(액상) | T6: MOCHA BLACK
E7: PURE CHOCO(액상) | F7: SHINY BROWN(액상) | G7: ALICIA BROWN TORIC | V7: 아이리스
C8: 피아 | E8: Natural black | F8: veil brown | G8: Ash brown(UV) | H8: almond brown | I8: old fashion | J8: milky gray | K8: Baby baby | L8: Cream nuts | M8: Water water | N8: cream beige | O8: cream grage | P8: PIA CHOCO | Q8: Skin beige | R8: Skin grage | S8: Skin Nude | T8: Fruite Punch | V8: 피아
E9: Layer Almond | F9: Layer Mist | G9: Layer Marron | H9: Virgin Cocoa | I9: Naked Rain | J9: Coconut | K9: Hot Chocolate | L9: Matcha Latte | M9: Lemonade | N9: Sheer Black | O9: Sheer Brown | P9: Olive Brown | Q9: Cappuccino | R9: Espresso | S9: Shiny Brown | T9: Lassie | V9: 피아
E10: Cider | F10: DATE TOPAZ | G10: HONEY AMBER | H10: Strawberry Quartz | I10: Lapis Lazuli | J10: PIA-OPAL | K10: PIA-PERIDOT | L10: CORAL BROWN | M10: SAKURA PETAL | N10: DAZZLE BEIGE | O10: MIRROR GRAY | P10: TINT BROWN | Q10: YAKISOBAPAN | R10: SABATEISHOKU | S10: DAZZLE GRAY | T10: TORIC(난시) | V10: 피아
E11: Airy BEIGE | F11: CHESTNUT | G11: TULLE BROWN | H11: CAFE MOCHA | I11: GREGE QUARTZ | J11: Amethyst | K11: Pearl Cats eye | L11: CITRINE | M11: HOJICHA LATTE | N11: TAMA KONNYAKU | O11: SMOKEY BEIGE | P11: SMOKEY GRAY | Q11: RUSTY BEIGE | R11: RUSTY GRAY | S11: RUSTY BEIGE(M) | T11: RUSTY GRAY(M) | V11: 피아
E12: RUSTY BROWN(M) | F12: FLAMINGO(M) | G12: OCEAN(M) | H12: MARIGOLD(M) | I12: DATE TOPAZ TORIC | J12: HAPPINESS CH | K12: KISS ME BROWN | L12: SECRET SHINE | M12: Prism gray | N12: DATE TOPAZ TORIC | O12: BROWN FONDUE | P12: SUGAR DONUT | Q12: Jelly Gray | R12: caramel souffle | S12: AIR GRAY | T12: PALM GREEN | V12: 피아
E13: TEDDY BROWN | F13: Strawberry quartz toric | G13: NUDIE BEGIE | H13: SAKURA SMORE | I13: MELTY MIST | J13: SMOKY QUARTZ | K13: GARNET | L13: TWIN TOPAZ | M13: OPAL TORIC | N13: AFFOGATO 55% | O13: COFFEE JELLY | P13: MELON PAN | Q13: ZUNDA MOCHI | R13: Churun chocofrappe | S13: Kyurukyuru darkmocha | T13: Fuwafuwa cappuccino
E14: Pururun Sodafloat | F14: MINI JEJE BROWNZE | G14: NEW ALMOND B | H14: Cinnamon Brown | I14: MAPLE MILKTEA | J14: POMME CANELE | K14: MELLOW STRAWBERRY | L14: CRYSTAL BLOOM | M14: RUTILATED DROP | N14: LADY BLACK | O14: LAIR PINK | P14: IDOL RING | Q14: HEROINE BROWN | R14: DAZZLE GRAY | S14: BROWN FONDUE TORIC | T14: TIRAMISU RING | V14: 피아
E15: SAKURA MOUSSE | F15: DOLLISH GRAY | G15: DOLLISH BROWN | H15: BUBBLE BLUE | I15: BROWN BUNNY | J15: GLOW BROWN | K15: CREAM ROSE | L15: DORAYAKI | M15: GEMHOUR | N15: TEMPURA | O15: ROSY BROWN | P15: SEPIA MOOD | Q15: CLASSIC BROWN | R15: MOON BROWN | S15: LASSIE NEO | T15: LADY MAUVE | V15: 피아
E16: SUEDE BEIGE | F16: BROWN CHOU | G16: LATTE PEARL | H16: COCO TOPAZ | I16: MOCHA RING | J16: SILKY PEARL | K16: COTTON RING | L16: MELADY BROWN | M16: UMI | N16: PURE NUDE | O16: SAKANA | P16: TARTE TATIN | Q16: FRUIT PUNCH NEO | R16: CINNAMON BROWN TORIC | S16: BLUEBERRY JAM | T16: KOALA GRAY | V16: 피아
E17: ALMOND BROWN TORIC | F17: SECRET TUTU BROWN | G17: OOLONG TEA | H17: BRULEE BROWN | I17: WHIP BROWN | J17: SMORE RING BROWN | K17: DARK PEONY(액상) | L17: HEAVEN SKY | M17: NIGHT SPARK | N17: BAD GIRL | O17: SPICY QUEEN | P17: UNIFORM BLACK | Q17: SALTY DONUT | R17: COCO TRUFFLE | S17: UNIFORM BLACK(M) | T17: DREAM GRAY | V17: 피아
E18: DARK PEONY | F18: DAZZLE GRAY TORIC | G18: GEM CHOCOLAT | H18: DOLLISH BROWN TORIC | I18: TARTE TATIN(M) | J18: DAZZLE GRAY(액상) | K18: ALMOND POODLE | L18: HONEY SODA | M18: TWINKLE BROWN | N18: PINK BOMB | O18: BRULEE PEARL | P18: MOON MELT BROWN | Q18: STAR GLOW | R18: PRINCESS CHOCOLAT | S18: CAT PEARL | T18: SUNNY BEAR | V18: 피아
E19: TRUFFLE GRAY | F19: MOCHA POWDER | G19: LOVE CACAO(액상) | H19: SUGAR PEARL | I19: DOLLISH GRAY(액상) | J19: BROWN BUNNY TORIC | K19: MELTY BUTTER | L19: MARIA RING | M19: SUGAR RIBBON(액상) | N19: CHOCO RIBBON(액상) | O19: STARFLARE GRAY(액상) | P19: STARFLARE BEIGE(액상) | Q19: JELLY QUARTZ(액상) | R19: ICONIC BROWN(액상) | S19: ICONIC GRAY(액상) | T19: DAYGLOW GRAY(액상)
E20: DAYGLOW BROWN(액상) | F20: SUGAR RIBBON_M(액상) | G20: MERMAID RING | H20: BABY ESPRESSO TORIC | I20: DOLLISH GRAY TORIC(액상) | J20: COFFEE JELLY TORIC(액상) | K20: GRAY BUNNY(액상) | L20: CHERISH BROWN(액상) | M20: CHOCO MIST(액상) | N20: CHAI CAFÉ(액상) | O20: BROWN BUNNY(액상) | P20: PINK BOMB(액상) | Q20: COFEE JELLY(액상) | R20: SAKURA SMORE(액상) | S20: TWINKLE BROWN(액상) | T20: AFFOGATO(액상) | V20: 피아
E21: DARK PEONY(액상) | F21: COFFEE JELLY(액상) | G21: MINI COFFEE JELLY(액상) | H21: DAZZLE BEIGE(액상) | I21: BABY ESPRESSO | J21: CHAMPAGNE PARTY(액상) | K21: CRYSTAL PARTY(액상) | V21: 벨라
C22: BELLA | E22: Ocean Blue | F22: Hazel Beige | G22: Radiant Hazel | H22: Citrine Crystal | I22: Bluish Gray(B) | J22: ALMOND BROWN(B) | K22: Platinum GRAY(B) | L22: ASH BROWN(B) | M22: ROSEWOOD | N22: HAZEL HONEY | O22: PINE | P22: BOB GRAY | Q22: VENUS | R22: EARTH | S22: MARS | T22: SIREN BRONZE(액상) | V22: 벨라
E23: NERELLE(액상) | F23: SILENT GRAY(액상) | V23: 렌즈미
C24: LENS ME | E24: Real Some Brown | F24: Real Some Choco | G24: REALFIT BROWN | H24: REALFIT GRAY | I24: YOUSON_BLACK TORIC(액상) | J24: YOUSON_BROWN TORIC(액상) | V24: 렌즈타운
C25: LENS TOWN | E25: Lighly Gray | F25: Lighly Brown | G25: Lighly Pure Gray | H25: Lighly Pure Brown | I25: Lighly Rose Gray | J25: Lighly Rose Beige | K25: Lighly Rose Rose | L25: Lighly Rose Khaki | M25: Lighly Rose Berry | N25: Lighly Rose Cacao | O25: LIGHLY CREAMY D_BLACK | P25: LIGHLY CREAMY D_ROSE | Q25: LIGHLY CREAMY D_GRAY | R25: LIGHLY CREAMY D_CHOCO | S25: LIGHLY CREAMY D_BROWN | V25: 프롬아이즈
C26: FROMEYES | E26: Lady Doll | F26: Mocha Brown | G26: Lady Pearl | H26: MilkTea Ash | I26: Silhouette Camel | J26: Gauss Chocolate | K26: Clear Beige | L26: Sweet Brown | M26: Airy Olive | N26: Brown Grege | O26: Chiffon Navy | P26: Clear Gray | Q26: Caramel Brown | R26: Dark Mint | S26: Cacao Brown | T26: Clear Beige Coral | V26: 프롬아이즈
E27: (New) Gauss 1DAY | F27: CREAM SPOON | G27: CARAMEL GRAGE | H27: clear beige coral mini | I27: clear beige mini | J27: MERRY TIARA | K27: PINK RABBIT | L27: JEWEL TREE | M27: JEWEL BERRY | N27: MELTING BROWN | O27: ASH GRAY | P27: CREAM VANILLA | Q27: COOL GRAY | R27: ORI ICE MUFFIN | V27: 호야
C28: 호야/아이키니 | E28: Casual Ash | F28: Aurora Gray | G28: Maquia Brown | H28: Noble Ash | I28: KYNY Brown | J28: KYNY Gray | K28: KYNY Light Gray | V28: 알콘
C29: ALCON | E29: ALLURE GRAY | G29: ALLURE HAZEL | H29: JEWEL GOLD | I29: JEWEL Black | J29: CHIC CARAMEL | K29: CHIC SMOKE | L29: satin maple | M29: ALLURE BLUE | V29: 알콘
C30: GEMHOUR | E30: ROSY BROWN | F30: BROWN(잼아워) | G30: GRAY(잼아워) | H30: LIZ BROWN | I30: GRETA BLACK | J30: LIA CHOCO | V30: 신시아
C31: Sincere | E31: Platinum GRAY | F31: HAZELNUT | G31: SIRIUS MISTY | H31: HIGHLIGHTER | I31: HOLOGRAM SHELL | J31: SUGAR MINT | K31: LAVENDER NUDE | L31: SILKY GINGER | M31: SUNGLOW RING | N31: MYSTIC BROWN | O31: OPAL GRAY | P31: CAFÉ NOIR | Q31: COSMIC LATTE | R31: COPPER ASH | S31: LUNA MAUVE | V31: 신시아
E32: ASH BROWN(S) | F32: RUSSIAN GRAY | G32: WATER BROWN | H32: PINK BROWN | I32: RED BROWN | J32: HAPPINESS CH | K32: HAZEL | L32: BROWN BEIGE | M32: SKY GRAY | N32: VENUS BELT | O32: KHAKI BROWN | P32: DOLLY BROWN | Q32: FLOWER BROWN | R32: SHINY BROWN(D) | S32: GREGE GRAY | T32: JELLY CORAL | V32: 신시아
E33: ENNUI GRAY | F33: NEUTRAL BROWN | G33: SHINY BROWN(D) | H33: AIR BEIGE | I33: LITTLE BROWN | J33: CHAI HOOP | V33: 피아 M
C34: PBT-PIA | E34: DAZZLE BEIGE(PBT) | F34: DAZZLE GRAY(PBT) | G34: CORAL BROWN(PBT) | H34: MIRROR GRAY(PBT) | I34: TINT BROWN(PBT) | J34: SAKURA PETAL(PBT) | K34: TANGERINE TEA(PBT) | L34: PEACH CRUSH(PBT) | M34: SAKURA SMORE(M) | N34: DARK PEONY(M) | O34: PUREE GREIGE | P34: DOLLISH GRAY_M | Q34: DOLLISH BROWN_M | R34: SKIN NUDE CHOCO_M | S34: COFFEE JELLY(M) | T34: AFFOGATO(M) 38% | V34: 피아 M
E35: BROWN BUNNY(M) | F35: DREAM GRAY (M) | G35: TIRAMISU RING(M) | H35: OOLONG TEA(M) | I35: PINK BOMB(M) | J35: TWINKLE BROWN(M) | K35: ALMOND POODLE(M) | L35: BRULEE PEARL(M) | M35: MELTY BUTTER(M) | N35: SUGAR PEARL(M) | O35: DATE TOPAZ(M) | P35: GARNET(M) | Q35: Water water(M) | R35: SKIN BEIGE(M) | S35: CREAM ROSE(M) | T35: STRAWBERRY QUARTZ_M | V35: 피아 M
E36: IDOL RING(M) | F36: LADY BLACK(M) | G36: JELLY QUARTZ_M(액상) | H36: PRINCESS CHOCOLAT_M | I36: CHOCO RIBBON_M(액상) | J36: MOCHA RING(M) | K36: GRAY BUNNY M(액상) | L36: CHERISH BROWN M(액상) | M36: CHAI CAFÉ M(액상) | N36: CHOCO MIST M(액상) | V36: 부티크
C37: Vision Boutique | E37: BASIL GREY | F37: STYLISH GREY | G37: OLIVE GREEN | H37: DEEP BLUE | V37: 포인룩
C38: 4INLOOK | E38: MIDU BROWN | F38: LITTLE NEW B | G38: LITTLE NEW G | H38: LOVE GRAY | I38: LOVE BROWN | J38: LADY Q GRAY | K38: LADY Q BROWN | L38: HELLO KITTY BROWN | M38: HELLO KITTY GRAY | V38: 소로티카
C39: SOLOTICA | E39: ARARA BLUE | F39: CAMBUCI GREEN | G39: BOSSANOVA GRAY | H39: BELEZA GRAY | I39: DANDARA HAZEL | J39: AMAZONIA | V39: O2O2
C40: O2O2 | E40: NATURAL BROWN EX | F40: NATURAL GRAY EX | G40: NATURAL CHOCOLAT EX | H40: MYSTI KHAKI EX | I40: MYSTI GRAY EX | J40: Sepia choco EX | K40: ash gray EX | L40: CHAMPAGNE PARTY(액상) | M40: BL HAZEL EX | N40: BL ROSE EX | O40: SOUL BROWN EX | P40: SEPIA CHOCO TORIC | V40: 아이큐
C41: 아이큐 | E41: ICE GRAY girl | F41: BABY RING | G41: AK BROWN | H41: MILK CHOC | I41: LOVE IS YOU | J41: LOVE ME TRUE | K41: LET ME GO | L41: LOVE ME TENDER | M41: SWEET CHOCO | N41: SNOW WINK | O41: GLOSS MOON | P41: CRYSTAL OLIVE | Q41: FOXY AMBER | R41: LOVE YOURSELF | S41: PINK CHOC | V41: 아시아 네트윅스
C42: ANW | E42: Style gray | F42: SPICY GRAY | G42: BITTER BROWN | H42: PINK OPAL | I42: INDIGO ASH | J42: DEAR BROWN | K42: Vesta Beige | L42: HAZEL BEIGE AC | M42: SUNNY HAZEL | N42: THROUGH BEIGE | O42: ACID HAZEL | P42: ART GRAY | Q42: AMBER BROWN | R42: CRÈME BROWN | S42: ANW DUSK BROWN | T42: DUSK BEIGE | V42: 아시아 네트윅스
E43: ANW_First love Kristin | F43: OVE TORIC T1 | G43: BAM BROWN(M) | H43: ANW_OLIVE | V43: 기타
...

Sheet 생산계획(잉크)
B2: 주간 잉크 생산계획 종합(Rev.41)
B6: * 주간 잉크 생산 계획(상세)
B7: 구분 | C7: 월 | H7: 화 | L7: 수 | P7: 목 | T7: 금 | X7: 토 | AB7: 일
C8: =사출계획!E60 -> 5/11 | H8: =사출계획!G60 -> 5/12 | L8: =사출계획!I60 -> 5/13 | P8: =사출계획!K60 -> 5/14 | T8: =사출계획!M60 -> 5/15 | X8: =사출계획!O60 -> 5/16 | AB8: =사출계획!Q60 -> 5/17
C9: 현재고 | D9: 가용일수 | E9: 필요수량 | F9: 제조량 | G9: 호기 | H9: 현재고 | I9: 가용일수 | J9: 제조량 | K9: 호기 | L9: 현재고 | M9: 가용일수 | N9: 제조량 | O9: 호기 | P9: 현재고 | Q9: 가용일수 | R9: 제조량 | S9: 호기 | T9: 현재고 | U9: 가용일수 | V9: 제조량 | W9: 호기 | X9: 현재고 | Y9: 가용일수 | Z9: 제조량 | AA9: 호기 | AB9: 현재고 | AC9: 가용일수 | AD9: 제조량 | AE9: 호기
B10: SOUL | D10: =IFERROR(C10/INDEX(표5[#All],MATCH(B10,표5[[#All],[잉크]],0),2),"") | E10: =$C10-INDEX(표5[#All],MATCH(B10,표5[[#All],[잉크]],0),24) -> 0 | G10: =IF(ISBLANK(F10),"",INDEX(호기!$A$1:$B$657,MATCH('생산계획(잉크)'!B462,호기!$A$1:$A$657,0),2)) | H10: =C10+F10-INDEX(표5[#All],MATCH(B10,표5[[#All],[잉크]],0),2) -> 0 | I10: =IFERROR(H10/INDEX(표5[#All],MATCH(B10,표5[[#All],[잉크]],0),5),"") | K10: =IF(ISBLANK(J10),"",INDEX(호기!$A$1:$B$657,MATCH('생산계획(잉크)'!B462,호기!$A$1:$A$657,0),2)) | L10: =H10+J10-INDEX(표5[#All],MATCH(B10,표5[[#All],[잉크]],0),5) -> 0 | M10: =IFERROR(L10/INDEX(표5[#All],MATCH(B10,표5[[#All],[잉크]],0),8),"") | O10: =IF(ISBLANK(N10),"",INDEX(호기!$A$1:$B$657,MATCH('생산계획(잉크)'!B462,호기!$A$1:$A$657,0),2)) | P10: =L10+N10-INDEX(표5[#All],MATCH(B10,표5[[#All],[잉크]],0),5) -> 0 | Q10: =IFERROR(P10/INDEX(표5[#All],MATCH(B10,표5[[#All],[잉크]],0),11),"") | S10: =IF(ISBLANK(R10),"",INDEX(호기!$A$1:$B$657,MATCH('생산계획(잉크)'!B462,호기!$A$1:$A$657,0),2)) | T10: =P10+R10-INDEX(표5[#All],MATCH(B10,표5[[#All],[잉크]],0),5) -> 0 | U10: =IFERROR(T10/INDEX(표5[#All],MATCH(B10,표5[[#All],[잉크]],0),14),"") | W10: =IF(ISBLANK(V10),"",INDEX(호기!$A$1:$B$657,MATCH('생산계획(잉크)'!B462,호기!$A$1:$A$657,0),2)) | X10: =T10+V10-INDEX(표5[#All],MATCH(B10,표5[[#All],[잉크]],0),5) -> 0 | Y10: =IFERROR(X10/INDEX(표5[#All],MATCH(B10,표5[[#All],[잉크]],0),17),"") | AA10: =IF(ISBLANK(Z10),"",INDEX(호기!$A$1:$B$657,MATCH('생산계획(잉크)'!B462,호기!$A$1:$A$657,0),2)) | AB10: =X10+Z10-INDEX(표5[#All],MATCH(B10,표5[[#All],[잉크]],0),5) -> 0 | AC10: =IFERROR(AB10/INDEX(표5[#All],MATCH(B10,표5[[#All],[잉크]],0),20),"")
B11: WOOD | D11: =IFERROR(C11/INDEX(표5[#All],MATCH(B11,표5[[#All],[잉크]],0),2),"") | E11: =$C11-INDEX(표5[#All],MATCH(B11,표5[[#All],[잉크]],0),24) -> 0 | G11: =IF(ISBLANK(F11),"",INDEX(호기!$A$1:$B$657,MATCH('생산계획(잉크)'!B463,호기!$A$1:$A$657,0),2)) | H11: =C11+F11-INDEX(표5[#All],MATCH(B11,표5[[#All],[잉크]],0),2) -> 0 | I11: =IFERROR(H11/INDEX(표5[#All],MATCH(B11,표5[[#All],[잉크]],0),5),"") | K11: =IF(ISBLANK(J11),"",INDEX(호기!$A$1:$B$657,MATCH('생산계획(잉크)'!B463,호기!$A$1:$A$657,0),2)) | L11: =H11+J11-INDEX(표5[#All],MATCH(B11,표5[[#All],[잉크]],0),5) -> 0 | M11: =IFERROR(L11/INDEX(표5[#All],MATCH(B11,표5[[#All],[잉크]],0),8),"") | O11: =IF(ISBLANK(N11),"",INDEX(호기!$A$1:$B$657,MATCH('생산계획(잉크)'!B463,호기!$A$1:$A$657,0),2)) | P11: =L11+N11-INDEX(표5[#All],MATCH(B11,표5[[#All],[잉크]],0),5) -> 0 | Q11: =IFERROR(P11/INDEX(표5[#All],MATCH(B11,표5[[#All],[잉크]],0),11),"") | S11: =IF(ISBLANK(R11),"",INDEX(호기!$A$1:$B$657,MATCH('생산계획(잉크)'!B463,호기!$A$1:$A$657,0),2)) | T11: =P11+R11-INDEX(표5[#All],MATCH(B11,표5[[#All],[잉크]],0),5) -> 0 | U11: =IFERROR(T11/INDEX(표5[#All],MATCH(B11,표5[[#All],[잉크]],0),14),"") | W11: =IF(ISBLANK(V11),"",INDEX(호기!$A$1:$B$657,MATCH('생산계획(잉크)'!B463,호기!$A$1:$A$657,0),2)) | X11: =T11+V11-INDEX(표5[#All],MATCH(B11,표5[[#All],[잉크]],0),5) -> 0 | Y11: =IFERROR(X11/INDEX(표5[#All],MATCH(B11,표5[[#All],[잉크]],0),17),"") | AA11: =IF(ISBLANK(Z11),"",INDEX(호기!$A$1:$B$657,MATCH('생산계획(잉크)'!B463,호기!$A$1:$A$657,0),2)) | AB11: =X11+Z11-INDEX(표5[#All],MATCH(B11,표5[[#All],[잉크]],0),5) -> 0 | AC11: =IFERROR(AB11/INDEX(표5[#All],MATCH(B11,표5[[#All],[잉크]],0),20),"")
B12: POGBA | D12: =IFERROR(C12/INDEX(표5[#All],MATCH(B12,표5[[#All],[잉크]],0),2),"") | E12: =$C12-INDEX(표5[#All],MATCH(B12,표5[[#All],[잉크]],0),24) -> 0 | G12: =IF(ISBLANK(F12),"",INDEX(호기!$A$1:$B$657,MATCH('생산계획(잉크)'!B464,호기!$A$1:$A$657,0),2)) | H12: =C12+F12-INDEX(표5[#All],MATCH(B12,표5[[#All],[잉크]],0),2) -> 0 | I12: =IFERROR(H12/INDEX(표5[#All],MATCH(B12,표5[[#All],[잉크]],0),5),"") | K12: =IF(ISBLANK(J12),"",INDEX(호기!$A$1:$B$657,MATCH('생산계획(잉크)'!B464,호기!$A$1:$A$657,0),2)) | L12: =H12+J12-INDEX(표5[#All],MATCH(B12,표5[[#All],[잉크]],0),5) -> 0 | M12: =IFERROR(L12/INDEX(표5[#All],MATCH(B12,표5[[#All],[잉크]],0),8),"") | O12: =IF(ISBLANK(N12),"",INDEX(호기!$A$1:$B$657,MATCH('생산계획(잉크)'!B464,호기!$A$1:$A$657,0),2)) | P12: =L12+N12-INDEX(표5[#All],MATCH(B12,표5[[#All],[잉크]],0),5) -> 0 | Q12: =IFERROR(P12/INDEX(표5[#All],MATCH(B12,표5[[#All],[잉크]],0),11),"") | S12: =IF(ISBLANK(R12),"",INDEX(호기!$A$1:$B$657,MATCH('생산계획(잉크)'!B464,호기!$A$1:$A$657,0),2)) | T12: =P12+R12-INDEX(표5[#All],MATCH(B12,표5[[#All],[잉크]],0),5) -> 0 | U12: =IFERROR(T12/INDEX(표5[#All],MATCH(B12,표5[[#All],[잉크]],0),14),"") | W12: =IF(ISBLANK(V12),"",INDEX(호기!$A$1:$B$657,MATCH('생산계획(잉크)'!B464,호기!$A$1:$A$657,0),2)) | X12: =T12+V12-INDEX(표5[#All],MATCH(B12,표5[[#All],[잉크]],0),5) -> 0 | Y12: =IFERROR(X12/INDEX(표5[#All],MATCH(B12,표5[[#All],[잉크]],0),17),"") | AA12: =IF(ISBLANK(Z12),"",INDEX(호기!$A$1:$B$657,MATCH('생산계획(잉크)'!B464,호기!$A$1:$A$657,0),2)) | AB12: =X12+Z12-INDEX(표5[#All],MATCH(B12,표5[[#All],[잉크]],0),5) -> 0 | AC12: =IFERROR(AB12/INDEX(표5[#All],MATCH(B12,표5[[#All],[잉크]],0),20),"")
B13: LUXE | D13: =IFERROR(C13/INDEX(표5[#All],MATCH(B13,표5[[#All],[잉크]],0),2),"") | E13: =$C13-INDEX(표5[#All],MATCH(B13,표5[[#All],[잉크]],0),24) -> 0 | G13: =IF(ISBLANK(F13),"",INDEX(호기!$A$1:$B$657,MATCH('생산계획(잉크)'!B465,호기!$A$1:$A$657,0),2)) | H13: =C13+F13-INDEX(표5[#All],MATCH(B13,표5[[#All],[잉크]],0),2) -> 0 | I13: =IFERROR(H13/INDEX(표5[#All],MATCH(B13,표5[[#All],[잉크]],0),5),"") | K13: =IF(ISBLANK(J13),"",INDEX(호기!$A$1:$B$657,MATCH('생산계획(잉크)'!B465,호기!$A$1:$A$657,0),2)) | L13: =H13+J13-INDEX(표5[#All],MATCH(B13,표5[[#All],[잉크]],0),5) -> 0 | M13: =IFERROR(L13/INDEX(표5[#All],MATCH(B13,표5[[#All],[잉크]],0),8),"") | O13: =IF(ISBLANK(N13),"",INDEX(호기!$A$1:$B$657,MATCH('생산계획(잉크)'!B465,호기!$A$1:$A$657,0),2)) | P13: =L13+N13-INDEX(표5[#All],MATCH(B13,표5[[#All],[잉크]],0),5) -> 0 | Q13: =IFERROR(P13/INDEX(표5[#All],MATCH(B13,표5[[#All],[잉크]],0),11),"") | S13: =IF(ISBLANK(R13),"",INDEX(호기!$A$1:$B$657,MATCH('생산계획(잉크)'!B465,호기!$A$1:$A$657,0),2)) | T13: =P13+R13-INDEX(표5[#All],MATCH(B13,표5[[#All],[잉크]],0),5) -> 0 | U13: =IFERROR(T13/INDEX(표5[#All],MATCH(B13,표5[[#All],[잉크]],0),14),"") | W13: =IF(ISBLANK(V13),"",INDEX(호기!$A$1:$B$657,MATCH('생산계획(잉크)'!B465,호기!$A$1:$A$657,0),2)) | X13: =T13+V13-INDEX(표5[#All],MATCH(B13,표5[[#All],[잉크]],0),5) -> 0 | Y13: =IFERROR(X13/INDEX(표5[#All],MATCH(B13,표5[[#All],[잉크]],0),17),"") | AA13: =IF(ISBLANK(Z13),"",INDEX(호기!$A$1:$B$657,MATCH('생산계획(잉크)'!B465,호기!$A$1:$A$657,0),2)) | AB13: =X13+Z13-INDEX(표5[#All],MATCH(B13,표5[[#All],[잉크]],0),5) -> 0 | AC13: =IFERROR(AB13/INDEX(표5[#All],MATCH(B13,표5[[#All],[잉크]],0),20),"")
B14: VANTA | D14: =IFERROR(C14/INDEX(표5[#All],MATCH(B14,표5[[#All],[잉크]],0),2),"") | E14: =$C14-INDEX(표5[#All],MATCH(B14,표5[[#All],[잉크]],0),24) -> 0 | G14: =IF(ISBLANK(F14),"",INDEX(호기!$A$1:$B$657,MATCH('생산계획(잉크)'!B466,호기!$A$1:$A$657,0),2)) | H14: =C14+F14-INDEX(표5[#All],MATCH(B14,표5[[#All],[잉크]],0),2) -> 0 | I14: =IFERROR(H14/INDEX(표5[#All],MATCH(B14,표5[[#All],[잉크]],0),5),"") | K14: =IF(ISBLANK(J14),"",INDEX(호기!$A$1:$B$657,MATCH('생산계획(잉크)'!B466,호기!$A$1:$A$657,0),2)) | L14: =H14+J14-INDEX(표5[#All],MATCH(B14,표5[[#All],[잉크]],0),5) -> 0 | M14: =IFERROR(L14/INDEX(표5[#All],MATCH(B14,표5[[#All],[잉크]],0),8),"") | O14: =IF(ISBLANK(N14),"",INDEX(호기!$A$1:$B$657,MATCH('생산계획(잉크)'!B466,호기!$A$1:$A$657,0),2)) | P14: =L14+N14-INDEX(표5[#All],MATCH(B14,표5[[#All],[잉크]],0),5) -> 0 | Q14: =IFERROR(P14/INDEX(표5[#All],MATCH(B14,표5[[#All],[잉크]],0),11),"") | S14: =IF(ISBLANK(R14),"",INDEX(호기!$A$1:$B$657,MATCH('생산계획(잉크)'!B466,호기!$A$1:$A$657,0),2)) | T14: =P14+R14-INDEX(표5[#All],MATCH(B14,표5[[#All],[잉크]],0),5) -> 0 | U14: =IFERROR(T14/INDEX(표5[#All],MATCH(B14,표5[[#All],[잉크]],0),14),"") | W14: =IF(ISBLANK(V14),"",INDEX(호기!$A$1:$B$657,MATCH('생산계획(잉크)'!B466,호기!$A$1:$A$657,0),2)) | X14: =T14+V14-INDEX(표5[#All],MATCH(B14,표5[[#All],[잉크]],0),5) -> 0 | Y14: =IFERROR(X14/INDEX(표5[#All],MATCH(B14,표5[[#All],[잉크]],0),17),"") | AA14: =IF(ISBLANK(Z14),"",INDEX(호기!$A$1:$B$657,MATCH('생산계획(잉크)'!B466,호기!$A$1:$A$657,0),2)) | AB14: =X14+Z14-INDEX(표5[#All],MATCH(B14,표5[[#All],[잉크]],0),5) -> 0 | AC14: =IFERROR(AB14/INDEX(표5[#All],MATCH(B14,표5[[#All],[잉크]],0),20),"")
B15: SHADOW | C15: 1 | D15: =IFERROR(C15/INDEX(표5[#All],MATCH(B15,표5[[#All],[잉크]],0),2),"") -> 1 | E15: =$C15-INDEX(표5[#All],MATCH(B15,표5[[#All],[잉크]],0),24) -> -5 | G15: =IF(ISBLANK(F15),"",INDEX(호기!$A$1:$B$657,MATCH('생산계획(잉크)'!B467,호기!$A$1:$A$657,0),2)) | H15: =C15+F15-INDEX(표5[#All],MATCH(B15,표5[[#All],[잉크]],0),2)+4 -> 4 | I15: =IFERROR(H15/INDEX(표5[#All],MATCH(B15,표5[[#All],[잉크]],0),5),"") -> 2 | K15: =IF(ISBLANK(J15),"",INDEX(호기!$A$1:$B$657,MATCH('생산계획(잉크)'!B467,호기!$A$1:$A$657,0),2)) | L15: =H15+J15-INDEX(표5[#All],MATCH(B15,표5[[#All],[잉크]],0),5) -> 2 | M15: =IFERROR(L15/INDEX(표5[#All],MATCH(B15,표5[[#All],[잉크]],0),8),"") | O15: =IF(ISBLANK(N15),"",INDEX(호기!$A$1:$B$657,MATCH('생산계획(잉크)'!B467,호기!$A$1:$A$657,0),2)) | P15: =L15+N15-INDEX(표5[#All],MATCH(B15,표5[[#All],[잉크]],0),5) -> 0 | Q15: =IFERROR(P15/INDEX(표5[#All],MATCH(B15,표5[[#All],[잉크]],0),11),"") | S15: =IF(ISBLANK(R15),"",INDEX(호기!$A$1:$B$657,MATCH('생산계획(잉크)'!B467,호기!$A$1:$A$657,0),2)) | T15: =P15+R15-INDEX(표5[#All],MATCH(B15,표5[[#All],[잉크]],0),5) -> -2 | U15: =IFERROR(T15/INDEX(표5[#All],MATCH(B15,표5[[#All],[잉크]],0),14),"") | W15: =IF(ISBLANK(V15),"",INDEX(호기!$A$1:$B$657,MATCH('생산계획(잉크)'!B467,호기!$A$1:$A$657,0),2)) | X15: =T15+V15-INDEX(표5[#All],MATCH(B15,표5[[#All],[잉크]],0),5) -> -4 | Y15: =IFERROR(X15/INDEX(표5[#All],MATCH(B15,표5[[#All],[잉크]],0),17),"") | AA15: =IF(ISBLANK(Z15),"",INDEX(호기!$A$1:$B$657,MATCH('생산계획(잉크)'!B467,호기!$A$1:$A$657,0),2)) | AB15: =X15+Z15-INDEX(표5[#All],MATCH(B15,표5[[#All],[잉크]],0),5) -> -6 | AC15: =IFERROR(AB15/INDEX(표5[#All],MATCH(B15,표5[[#All],[잉크]],0),20),"")
B16: JAZZ | C16: 0 | D16: =IFERROR(C16/INDEX(표5[#All],MATCH(B16,표5[[#All],[잉크]],0),2),"") -> 0 | E16: =$C16-INDEX(표5[#All],MATCH(B16,표5[[#All],[잉크]],0),24) -> -6 | F16: 3 | G16: =IF(ISBLANK(F16),"",INDEX(호기!$A$1:$B$657,MATCH('생산계획(잉크)'!B468,호기!$A$1:$A$657,0),2)) -> 3호기 | H16: =C16+F16-INDEX(표5[#All],MATCH(B16,표5[[#All],[잉크]],0),2)+1 -> 3 | I16: =IFERROR(H16/INDEX(표5[#All],MATCH(B16,표5[[#All],[잉크]],0),5),"") -> 1.5 | K16: =IF(ISBLANK(J16),"",INDEX(호기!$A$1:$B$657,MATCH('생산계획(잉크)'!B468,호기!$A$1:$A$657,0),2)) | L16: =H16+J16-INDEX(표5[#All],MATCH(B16,표5[[#All],[잉크]],0),5) -> 1 | M16: =IFERROR(L16/INDEX(표5[#All],MATCH(B16,표5[[#All],[잉크]],0),8),"") | O16: =IF(ISBLANK(N16),"",INDEX(호기!$A$1:$B$657,MATCH('생산계획(잉크)'!B468,호기!$A$1:$A$657,0),2)) | P16: =L16+N16-INDEX(표5[#All],MATCH(B16,표5[[#All],[잉크]],0),5) -> -1 | Q16: =IFERROR(P16/INDEX(표5[#All],MATCH(B16,표5[[#All],[잉크]],0),11),"") | S16: =IF(ISBLANK(R16),"",INDEX(호기!$A$1:$B$657,MATCH('생산계획(잉크)'!B468,호기!$A$1:$A$657,0),2)) | T16: =P16+R16-INDEX(표5[#All],MATCH(B16,표5[[#All],[잉크]],0),5) -> -3 | U16: =IFERROR(T16/INDEX(표5[#All],MATCH(B16,표5[[#All],[잉크]],0),14),"") | W16: =IF(ISBLANK(V16),"",INDEX(호기!$A$1:$B$657,MATCH('생산계획(잉크)'!B468,호기!$A$1:$A$657,0),2)) | X16: =T16+V16-INDEX(표5[#All],MATCH(B16,표5[[#All],[잉크]],0),5) -> -5 | Y16: =IFERROR(X16/INDEX(표5[#All],MATCH(B16,표5[[#All],[잉크]],0),17),"") | AA16: =IF(ISBLANK(Z16),"",INDEX(호기!$A$1:$B$657,MATCH('생산계획(잉크)'!B468,호기!$A$1:$A$657,0),2)) | AB16: =X16+Z16-INDEX(표5[#All],MATCH(B16,표5[[#All],[잉크]],0),5) -> -7 | AC16: =IFERROR(AB16/INDEX(표5[#All],MATCH(B16,표5[[#All],[잉크]],0),20),"")
B17: DARK | D17: =IFERROR(C17/INDEX(표5[#All],MATCH(B17,표5[[#All],[잉크]],0),2),"") | E17: =$C17-INDEX(표5[#All],MATCH(B17,표5[[#All],[잉크]],0),24) -> 0 | G17: =IF(ISBLANK(F17),"",INDEX(호기!$A$1:$B$657,MATCH('생산계획(잉크)'!B469,호기!$A$1:$A$657,0),2)) | H17: =C17+F17-INDEX(표5[#All],MATCH(B17,표5[[#All],[잉크]],0),2) -> 0 | I17: =IFERROR(H17/INDEX(표5[#All],MATCH(B17,표5[[#All],[잉크]],0),5),"") | K17: =IF(ISBLANK(J17),"",INDEX(호기!$A$1:$B$657,MATCH('생산계획(잉크)'!B469,호기!$A$1:$A$657,0),2)) | L17: =H17+J17-INDEX(표5[#All],MATCH(B17,표5[[#All],[잉크]],0),5) -> 0 | M17: =IFERROR(L17/INDEX(표5[#All],MATCH(B17,표5[[#All],[잉크]],0),8),"") | O17: =IF(ISBLANK(N17),"",INDEX(호기!$A$1:$B$657,MATCH('생산계획(잉크)'!B469,호기!$A$1:$A$657,0),2)) | P17: =L17+N17-INDEX(표5[#All],MATCH(B17,표5[[#All],[잉크]],0),5) -> 0 | Q17: =IFERROR(P17/INDEX(표5[#All],MATCH(B17,표5[[#All],[잉크]],0),11),"") | S17: =IF(ISBLANK(R17),"",INDEX(호기!$A$1:$B$657,MATCH('생산계획(잉크)'!B469,호기!$A$1:$A$657,0),2)) | T17: =P17+R17-INDEX(표5[#All],MATCH(B17,표5[[#All],[잉크]],0),5) -> 0 | U17: =IFERROR(T17/INDEX(표5[#All],MATCH(B17,표5[[#All],[잉크]],0),14),"") | W17: =IF(ISBLANK(V17),"",INDEX(호기!$A$1:$B$657,MATCH('생산계획(잉크)'!B469,호기!$A$1:$A$657,0),2)) | X17: =T17+V17-INDEX(표5[#All],MATCH(B17,표5[[#All],[잉크]],0),5) -> 0 | Y17: =IFERROR(X17/INDEX(표5[#All],MATCH(B17,표5[[#All],[잉크]],0),17),"") | AA17: =IF(ISBLANK(Z17),"",INDEX(호기!$A$1:$B$657,MATCH('생산계획(잉크)'!B469,호기!$A$1:$A$657,0),2)) | AB17: =X17+Z17-INDEX(표5[#All],MATCH(B17,표5[[#All],[잉크]],0),5) -> 0 | AC17: =IFERROR(AB17/INDEX(표5[#All],MATCH(B17,표5[[#All],[잉크]],0),20),"")
B18: CMBRICK | D18: =IFERROR(C18/INDEX(표5[#All],MATCH(B18,표5[[#All],[잉크]],0),2),"") | E18: =$C18-INDEX(표5[#All],MATCH(B18,표5[[#All],[잉크]],0),24) -> 0 | G18: =IF(ISBLANK(F18),"",INDEX(호기!$A$1:$B$657,MATCH('생산계획(잉크)'!B470,호기!$A$1:$A$657,0),2)) | H18: =C18+F18-INDEX(표5[#All],MATCH(B18,표5[[#All],[잉크]],0),2) -> 0 | I18: =IFERROR(H18/INDEX(표5[#All],MATCH(B18,표5[[#All],[잉크]],0),5),"") | K18: =IF(ISBLANK(J18),"",INDEX(호기!$A$1:$B$657,MATCH('생산계획(잉크)'!B470,호기!$A$1:$A$657,0),2)) | L18: =H18+J18-INDEX(표5[#All],MATCH(B18,표5[[#All],[잉크]],0),5) -> 0 | M18: =IFERROR(L18/INDEX(표5[#All],MATCH(B18,표5[[#All],[잉크]],0),8),"") | O18: =IF(ISBLANK(N18),"",INDEX(호기!$A$1:$B$657,MATCH('생산계획(잉크)'!B470,호기!$A$1:$A$657,0),2)) | P18: =L18+N18-INDEX(표5[#All],MATCH(B18,표5[[#All],[잉크]],0),5) -> 0 | Q18: =IFERROR(P18/INDEX(표5[#All],MATCH(B18,표5[[#All],[잉크]],0),11),"") | S18: =IF(ISBLANK(R18),"",INDEX(호기!$A$1:$B$657,MATCH('생산계획(잉크)'!B470,호기!$A$1:$A$657,0),2)) | T18: =P18+R18-INDEX(표5[#All],MATCH(B18,표5[[#All],[잉크]],0),5) -> 0 | U18: =IFERROR(T18/INDEX(표5[#All],MATCH(B18,표5[[#All],[잉크]],0),14),"") | W18: =IF(ISBLANK(V18),"",INDEX(호기!$A$1:$B$657,MATCH('생산계획(잉크)'!B470,호기!$A$1:$A$657,0),2)) | X18: =T18+V18-INDEX(표5[#All],MATCH(B18,표5[[#All],[잉크]],0),5) -> 0 | Y18: =IFERROR(X18/INDEX(표5[#All],MATCH(B18,표5[[#All],[잉크]],0),17),"") | AA18: =IF(ISBLANK(Z18),"",INDEX(호기!$A$1:$B$657,MATCH('생산계획(잉크)'!B470,호기!$A$1:$A$657,0),2)) | AB18: =X18+Z18-INDEX(표5[#All],MATCH(B18,표5[[#All],[잉크]],0),5) -> 0 | AC18: =IFERROR(AB18/INDEX(표5[#All],MATCH(B18,표5[[#All],[잉크]],0),20),"")
B19: VAMPIRE | D19: =IFERROR(C19/INDEX(표5[#All],MATCH(B19,표5[[#All],[잉크]],0),2),"") | E19: =$C19-INDEX(표5[#All],MATCH(B19,표5[[#All],[잉크]],0),24) -> 0 | G19: =IF(ISBLANK(F19),"",INDEX(호기!$A$1:$B$657,MATCH('생산계획(잉크)'!B471,호기!$A$1:$A$657,0),2)) | H19: =C19+F19-INDEX(표5[#All],MATCH(B19,표5[[#All],[잉크]],0),2) -> 0 | I19: =IFERROR(H19/INDEX(표5[#All],MATCH(B19,표5[[#All],[잉크]],0),5),"") | K19: =IF(ISBLANK(J19),"",INDEX(호기!$A$1:$B$657,MATCH('생산계획(잉크)'!B471,호기!$A$1:$A$657,0),2)) | L19: =H19+J19-INDEX(표5[#All],MATCH(B19,표5[[#All],[잉크]],0),5) -> 0 | M19: =IFERROR(L19/INDEX(표5[#All],MATCH(B19,표5[[#All],[잉크]],0),8),"") | O19: =IF(ISBLANK(N19),"",INDEX(호기!$A$1:$B$657,MATCH('생산계획(잉크)'!B471,호기!$A$1:$A$657,0),2)) | P19: =L19+N19-INDEX(표5[#All],MATCH(B19,표5[[#All],[잉크]],0),5) -> 0 | Q19: =IFERROR(P19/INDEX(표5[#All],MATCH(B19,표5[[#All],[잉크]],0),11),"") | S19: =IF(ISBLANK(R19),"",INDEX(호기!$A$1:$B$657,MATCH('생산계획(잉크)'!B471,호기!$A$1:$A$657,0),2)) | T19: =P19+R19-INDEX(표5[#All],MATCH(B19,표5[[#All],[잉크]],0),5) -> 0 | U19: =IFERROR(T19/INDEX(표5[#All],MATCH(B19,표5[[#All],[잉크]],0),14),"") | W19: =IF(ISBLANK(V19),"",INDEX(호기!$A$1:$B$657,MATCH('생산계획(잉크)'!B471,호기!$A$1:$A$657,0),2)) | X19: =T19+V19-INDEX(표5[#All],MATCH(B19,표5[[#All],[잉크]],0),5) -> 0 | Y19: =IFERROR(X19/INDEX(표5[#All],MATCH(B19,표5[[#All],[잉크]],0),17),"") | AA19: =IF(ISBLANK(Z19),"",INDEX(호기!$A$1:$B$657,MATCH('생산계획(잉크)'!B471,호기!$A$1:$A$657,0),2)) | AB19: =X19+Z19-INDEX(표5[#All],MATCH(B19,표5[[#All],[잉크]],0),5) -> 0 | AC19: =IFERROR(AB19/INDEX(표5[#All],MATCH(B19,표5[[#All],[잉크]],0),20),"")
B20: BRONZE | D20: =IFERROR(C20/INDEX(표5[#All],MATCH(B20,표5[[#All],[잉크]],0),2),"") | E20: =$C20-INDEX(표5[#All],MATCH(B20,표5[[#All],[잉크]],0),24) -> 0 | G20: =IF(ISBLANK(F20),"",INDEX(호기!$A$1:$B$657,MATCH('생산계획(잉크)'!B472,호기!$A$1:$A$657,0),2)) | H20: =C20+F20-INDEX(표5[#All],MATCH(B20,표5[[#All],[잉크]],0),2) -> 0 | I20: =IFERROR(H20/INDEX(표5[#All],MATCH(B20,표5[[#All],[잉크]],0),5),"") | K20: =IF(ISBLANK(J20),"",INDEX(호기!$A$1:$B$657,MATCH('생산계획(잉크)'!B472,호기!$A$1:$A$657,0),2)) | L20: =H20+J20-INDEX(표5[#All],MATCH(B20,표5[[#All],[잉크]],0),5) -> 0 | M20: =IFERROR(L20/INDEX(표5[#All],MATCH(B20,표5[[#All],[잉크]],0),8),"") | O20: =IF(ISBLANK(N20),"",INDEX(호기!$A$1:$B$657,MATCH('생산계획(잉크)'!B472,호기!$A$1:$A$657,0),2)) | P20: =L20+N20-INDEX(표5[#All],MATCH(B20,표5[[#All],[잉크]],0),5) -> 0 | Q20: =IFERROR(P20/INDEX(표5[#All],MATCH(B20,표5[[#All],[잉크]],0),11),"") | S20: =IF(ISBLANK(R20),"",INDEX(호기!$A$1:$B$657,MATCH('생산계획(잉크)'!B472,호기!$A$1:$A$657,0),2)) | T20: =P20+R20-INDEX(표5[#All],MATCH(B20,표5[[#All],[잉크]],0),5) -> 0 | U20: =IFERROR(T20/INDEX(표5[#All],MATCH(B20,표5[[#All],[잉크]],0),14),"") | W20: =IF(ISBLANK(V20),"",INDEX(호기!$A$1:$B$657,MATCH('생산계획(잉크)'!B472,호기!$A$1:$A$657,0),2)) | X20: =T20+V20-INDEX(표5[#All],MATCH(B20,표5[[#All],[잉크]],0),5) -> 0 | Y20: =IFERROR(X20/INDEX(표5[#All],MATCH(B20,표5[[#All],[잉크]],0),17),"") | AA20: =IF(ISBLANK(Z20),"",INDEX(호기!$A$1:$B$657,MATCH('생산계획(잉크)'!B472,호기!$A$1:$A$657,0),2)) | AB20: =X20+Z20-INDEX(표5[#All],MATCH(B20,표5[[#All],[잉크]],0),5) -> 0 | AC20: =IFERROR(AB20/INDEX(표5[#All],MATCH(B20,표5[[#All],[잉크]],0),20),"")
B21: GAEUL | D21: =IFERROR(C21/INDEX(표5[#All],MATCH(B21,표5[[#All],[잉크]],0),2),"") | E21: =$C21-INDEX(표5[#All],MATCH(B21,표5[[#All],[잉크]],0),24) -> 0 | G21: =IF(ISBLANK(F21),"",INDEX(호기!$A$1:$B$657,MATCH('생산계획(잉크)'!B473,호기!$A$1:$A$657,0),2)) | H21: =C21+F21-INDEX(표5[#All],MATCH(B21,표5[[#All],[잉크]],0),2) -> 0 | I21: =IFERROR(H21/INDEX(표5[#All],MATCH(B21,표5[[#All],[잉크]],0),5),"") | K21: =IF(ISBLANK(J21),"",INDEX(호기!$A$1:$B$657,MATCH('생산계획(잉크)'!B473,호기!$A$1:$A$657,0),2)) | L21: =H21+J21-INDEX(표5[#All],MATCH(B21,표5[[#All],[잉크]],0),5) -> 0 | M21: =IFERROR(L21/INDEX(표5[#All],MATCH(B21,표5[[#All],[잉크]],0),8),"") | O21: =IF(ISBLANK(N21),"",INDEX(호기!$A$1:$B$657,MATCH('생산계획(잉크)'!B473,호기!$A$1:$A$657,0),2)) | P21: =L21+N21-INDEX(표5[#All],MATCH(B21,표5[[#All],[잉크]],0),5) -> 0 | Q21: =IFERROR(P21/INDEX(표5[#All],MATCH(B21,표5[[#All],[잉크]],0),11),"") | S21: =IF(ISBLANK(R21),"",INDEX(호기!$A$1:$B$657,MATCH('생산계획(잉크)'!B473,호기!$A$1:$A$657,0),2)) | T21: =P21+R21-INDEX(표5[#All],MATCH(B21,표5[[#All],[잉크]],0),5) -> 0 | U21: =IFERROR(T21/INDEX(표5[#All],MATCH(B21,표5[[#All],[잉크]],0),14),"") | W21: =IF(ISBLANK(V21),"",INDEX(호기!$A$1:$B$657,MATCH('생산계획(잉크)'!B473,호기!$A$1:$A$657,0),2)) | X21: =T21+V21-INDEX(표5[#All],MATCH(B21,표5[[#All],[잉크]],0),5) -> 0 | Y21: =IFERROR(X21/INDEX(표5[#All],MATCH(B21,표5[[#All],[잉크]],0),17),"") | AA21: =IF(ISBLANK(Z21),"",INDEX(호기!$A$1:$B$657,MATCH('생산계획(잉크)'!B473,호기!$A$1:$A$657,0),2)) | AB21: =X21+Z21-INDEX(표5[#All],MATCH(B21,표5[[#All],[잉크]],0),5) -> 0 | AC21: =IFERROR(AB21/INDEX(표5[#All],MATCH(B21,표5[[#All],[잉크]],0),20),"")
B22: NAK | D22: =IFERROR(C22/INDEX(표5[#All],MATCH(B22,표5[[#All],[잉크]],0),2),"") | E22: =$C22-INDEX(표5[#All],MATCH(B22,표5[[#All],[잉크]],0),24) -> 0 | G22: =IF(ISBLANK(F22),"",INDEX(호기!$A$1:$B$657,MATCH('생산계획(잉크)'!B474,호기!$A$1:$A$657,0),2)) | H22: =C22+F22-INDEX(표5[#All],MATCH(B22,표5[[#All],[잉크]],0),2) -> 0 | I22: =IFERROR(H22/INDEX(표5[#All],MATCH(B22,표5[[#All],[잉크]],0),5),"") | K22: =IF(ISBLANK(J22),"",INDEX(호기!$A$1:$B$657,MATCH('생산계획(잉크)'!B474,호기!$A$1:$A$657,0),2)) | L22: =H22+J22-INDEX(표5[#All],MATCH(B22,표5[[#All],[잉크]],0),5) -> 0 | M22: =IFERROR(L22/INDEX(표5[#All],MATCH(B22,표5[[#All],[잉크]],0),8),"") | O22: =IF(ISBLANK(N22),"",INDEX(호기!$A$1:$B$657,MATCH('생산계획(잉크)'!B474,호기!$A$1:$A$657,0),2)) | P22: =L22+N22-INDEX(표5[#All],MATCH(B22,표5[[#All],[잉크]],0),5) -> 0 | Q22: =IFERROR(P22/INDEX(표5[#All],MATCH(B22,표5[[#All],[잉크]],0),11),"") | S22: =IF(ISBLANK(R22),"",INDEX(호기!$A$1:$B$657,MATCH('생산계획(잉크)'!B474,호기!$A$1:$A$657,0),2)) | T22: =P22+R22-INDEX(표5[#All],MATCH(B22,표5[[#All],[잉크]],0),5) -> 0 | U22: =IFERROR(T22/INDEX(표5[#All],MATCH(B22,표5[[#All],[잉크]],0),14),"") | W22: =IF(ISBLANK(V22),"",INDEX(호기!$A$1:$B$657,MATCH('생산계획(잉크)'!B474,호기!$A$1:$A$657,0),2)) | X22: =T22+V22-INDEX(표5[#All],MATCH(B22,표5[[#All],[잉크]],0),5) -> 0 | Y22: =IFERROR(X22/INDEX(표5[#All],MATCH(B22,표5[[#All],[잉크]],0),17),"") | AA22: =IF(ISBLANK(Z22),"",INDEX(호기!$A$1:$B$657,MATCH('생산계획(잉크)'!B474,호기!$A$1:$A$657,0),2)) | AB22: =X22+Z22-INDEX(표5[#All],MATCH(B22,표5[[#All],[잉크]],0),5) -> 0 | AC22: =IFERROR(AB22/INDEX(표5[#All],MATCH(B22,표5[[#All],[잉크]],0),20),"")
B23: YUP | D23: =IFERROR(C23/INDEX(표5[#All],MATCH(B23,표5[[#All],[잉크]],0),2),"") | E23: =$C23-INDEX(표5[#All],MATCH(B23,표5[[#All],[잉크]],0),24) -> 0 | G23: =IF(ISBLANK(F23),"",INDEX(호기!$A$1:$B$657,MATCH('생산계획(잉크)'!B475,호기!$A$1:$A$657,0),2)) | H23: =C23+F23-INDEX(표5[#All],MATCH(B23,표5[[#All],[잉크]],0),2) -> 0 | I23: =IFERROR(H23/INDEX(표5[#All],MATCH(B23,표5[[#All],[잉크]],0),5),"") | K23: =IF(ISBLANK(J23),"",INDEX(호기!$A$1:$B$657,MATCH('생산계획(잉크)'!B475,호기!$A$1:$A$657,0),2)) | L23: =H23+J23-INDEX(표5[#All],MATCH(B23,표5[[#All],[잉크]],0),5) -> 0 | M23: =IFERROR(L23/INDEX(표5[#All],MATCH(B23,표5[[#All],[잉크]],0),8),"") | O23: =IF(ISBLANK(N23),"",INDEX(호기!$A$1:$B$657,MATCH('생산계획(잉크)'!B475,호기!$A$1:$A$657,0),2)) | P23: =L23+N23-INDEX(표5[#All],MATCH(B23,표5[[#All],[잉크]],0),5) -> 0 | Q23: =IFERROR(P23/INDEX(표5[#All],MATCH(B23,표5[[#All],[잉크]],0),11),"") | S23: =IF(ISBLANK(R23),"",INDEX(호기!$A$1:$B$657,MATCH('생산계획(잉크)'!B475,호기!$A$1:$A$657,0),2)) | T23: =P23+R23-INDEX(표5[#All],MATCH(B23,표5[[#All],[잉크]],0),5) -> 0 | U23: =IFERROR(T23/INDEX(표5[#All],MATCH(B23,표5[[#All],[잉크]],0),14),"") | W23: =IF(ISBLANK(V23),"",INDEX(호기!$A$1:$B$657,MATCH('생산계획(잉크)'!B475,호기!$A$1:$A$657,0),2)) | X23: =T23+V23-INDEX(표5[#All],MATCH(B23,표5[[#All],[잉크]],0),5) -> 0 | Y23: =IFERROR(X23/INDEX(표5[#All],MATCH(B23,표5[[#All],[잉크]],0),17),"") | AA23: =IF(ISBLANK(Z23),"",INDEX(호기!$A$1:$B$657,MATCH('생산계획(잉크)'!B475,호기!$A$1:$A$657,0),2)) | AB23: =X23+Z23-INDEX(표5[#All],MATCH(B23,표5[[#All],[잉크]],0),5) -> 0 | AC23: =IFERROR(AB23/INDEX(표5[#All],MATCH(B23,표5[[#All],[잉크]],0),20),"")
B24: BADA | D24: =IFERROR(C24/INDEX(표5[#All],MATCH(B24,표5[[#All],[잉크]],0),2),"") | E24: =$C24-INDEX(표5[#All],MATCH(B24,표5[[#All],[잉크]],0),24) -> 0 | G24: =IF(ISBLANK(F24),"",INDEX(호기!$A$1:$B$657,MATCH('생산계획(잉크)'!B476,호기!$A$1:$A$657,0),2)) | H24: =C24+F24-INDEX(표5[#All],MATCH(B24,표5[[#All],[잉크]],0),2) -> 0 | I24: =IFERROR(H24/INDEX(표5[#All],MATCH(B24,표5[[#All],[잉크]],0),5),"") | K24: =IF(ISBLANK(J24),"",INDEX(호기!$A$1:$B$657,MATCH('생산계획(잉크)'!B476,호기!$A$1:$A$657,0),2)) | L24: =H24+J24-INDEX(표5[#All],MATCH(B24,표5[[#All],[잉크]],0),5) -> 0 | M24: =IFERROR(L24/INDEX(표5[#All],MATCH(B24,표5[[#All],[잉크]],0),8),"") | O24: =IF(ISBLANK(N24),"",INDEX(호기!$A$1:$B$657,MATCH('생산계획(잉크)'!B476,호기!$A$1:$A$657,0),2)) | P24: =L24+N24-INDEX(표5[#All],MATCH(B24,표5[[#All],[잉크]],0),5) -> 0 | Q24: =IFERROR(P24/INDEX(표5[#All],MATCH(B24,표5[[#All],[잉크]],0),11),"") | S24: =IF(ISBLANK(R24),"",INDEX(호기!$A$1:$B$657,MATCH('생산계획(잉크)'!B476,호기!$A$1:$A$657,0),2)) | T24: =P24+R24-INDEX(표5[#All],MATCH(B24,표5[[#All],[잉크]],0),5) -> 0 | U24: =IFERROR(T24/INDEX(표5[#All],MATCH(B24,표5[[#All],[잉크]],0),14),"") | W24: =IF(ISBLANK(V24),"",INDEX(호기!$A$1:$B$657,MATCH('생산계획(잉크)'!B476,호기!$A$1:$A$657,0),2)) | X24: =T24+V24-INDEX(표5[#All],MATCH(B24,표5[[#All],[잉크]],0),5) -> 0 | Y24: =IFERROR(X24/INDEX(표5[#All],MATCH(B24,표5[[#All],[잉크]],0),17),"") | AA24: =IF(ISBLANK(Z24),"",INDEX(호기!$A$1:$B$657,MATCH('생산계획(잉크)'!B476,호기!$A$1:$A$657,0),2)) | AB24: =X24+Z24-INDEX(표5[#All],MATCH(B24,표5[[#All],[잉크]],0),5) -> 0 | AC24: =IFERROR(AB24/INDEX(표5[#All],MATCH(B24,표5[[#All],[잉크]],0),20),"")
B25: NEODUM | D25: =IFERROR(C25/INDEX(표5[#All],MATCH(B25,표5[[#All],[잉크]],0),2),"") | E25: =$C25-INDEX(표5[#All],MATCH(B25,표5[[#All],[잉크]],0),24) -> 0 | G25: =IF(ISBLANK(F25),"",INDEX(호기!$A$1:$B$657,MATCH('생산계획(잉크)'!B477,호기!$A$1:$A$657,0),2)) | H25: =C25+F25-INDEX(표5[#All],MATCH(B25,표5[[#All],[잉크]],0),2) -> 0 | I25: =IFERROR(H25/INDEX(표5[#All],MATCH(B25,표5[[#All],[잉크]],0),5),"") | K25: =IF(ISBLANK(J25),"",INDEX(호기!$A$1:$B$657,MATCH('생산계획(잉크)'!B477,호기!$A$1:$A$657,0),2)) | L25: =H25+J25-INDEX(표5[#All],MATCH(B25,표5[[#All],[잉크]],0),5) -> 0 | M25: =IFERROR(L25/INDEX(표5[#All],MATCH(B25,표5[[#All],[잉크]],0),8),"") | O25: =IF(ISBLANK(N25),"",INDEX(호기!$A$1:$B$657,MATCH('생산계획(잉크)'!B477,호기!$A$1:$A$657,0),2)) | P25: =L25+N25-INDEX(표5[#All],MATCH(B25,표5[[#All],[잉크]],0),5) -> 0 | Q25: =IFERROR(P25/INDEX(표5[#All],MATCH(B25,표5[[#All],[잉크]],0),11),"") | S25: =IF(ISBLANK(R25),"",INDEX(호기!$A$1:$B$657,MATCH('생산계획(잉크)'!B477,호기!$A$1:$A$657,0),2)) | T25: =P25+R25-INDEX(표5[#All],MATCH(B25,표5[[#All],[잉크]],0),5) -> 0 | U25: =IFERROR(T25/INDEX(표5[#All],MATCH(B25,표5[[#All],[잉크]],0),14),"") | W25: =IF(ISBLANK(V25),"",INDEX(호기!$A$1:$B$657,MATCH('생산계획(잉크)'!B477,호기!$A$1:$A$657,0),2)) | X25: =T25+V25-INDEX(표5[#All],MATCH(B25,표5[[#All],[잉크]],0),5) -> 0 | Y25: =IFERROR(X25/INDEX(표5[#All],MATCH(B25,표5[[#All],[잉크]],0),17),"") | AA25: =IF(ISBLANK(Z25),"",INDEX(호기!$A$1:$B$657,MATCH('생산계획(잉크)'!B477,호기!$A$1:$A$657,0),2)) | AB25: =X25+Z25-INDEX(표5[#All],MATCH(B25,표5[[#All],[잉크]],0),5) -> 0 | AC25: =IFERROR(AB25/INDEX(표5[#All],MATCH(B25,표5[[#All],[잉크]],0),20),"")
B26: ROYAL | D26: =IFERROR(C26/INDEX(표5[#All],MATCH(B26,표5[[#All],[잉크]],0),2),"") | E26: =$C26-INDEX(표5[#All],MATCH(B26,표5[[#All],[잉크]],0),24) -> 0 | G26: =IF(ISBLANK(F26),"",INDEX(호기!$A$1:$B$657,MATCH('생산계획(잉크)'!B478,호기!$A$1:$A$657,0),2)) | H26: =C26+F26-INDEX(표5[#All],MATCH(B26,표5[[#All],[잉크]],0),2) -> 0 | I26: =IFERROR(H26/INDEX(표5[#All],MATCH(B26,표5[[#All],[잉크]],0),5),"") | K26: =IF(ISBLANK(J26),"",INDEX(호기!$A$1:$B$657,MATCH('생산계획(잉크)'!B478,호기!$A$1:$A$657,0),2)) | L26: =H26+J26-INDEX(표5[#All],MATCH(B26,표5[[#All],[잉크]],0),5) -> 0 | M26: =IFERROR(L26/INDEX(표5[#All],MATCH(B26,표5[[#All],[잉크]],0),8),"") | O26: =IF(ISBLANK(N26),"",INDEX(호기!$A$1:$B$657,MATCH('생산계획(잉크)'!B478,호기!$A$1:$A$657,0),2)) | P26: =L26+N26-INDEX(표5[#All],MATCH(B26,표5[[#All],[잉크]],0),5) -> 0 | Q26: =IFERROR(P26/INDEX(표5[#All],MATCH(B26,표5[[#All],[잉크]],0),11),"") | S26: =IF(ISBLANK(R26),"",INDEX(호기!$A$1:$B$657,MATCH('생산계획(잉크)'!B478,호기!$A$1:$A$657,0),2)) | T26: =P26+R26-INDEX(표5[#All],MATCH(B26,표5[[#All],[잉크]],0),5) -> 0 | U26: =IFERROR(T26/INDEX(표5[#All],MATCH(B26,표5[[#All],[잉크]],0),14),"") | W26: =IF(ISBLANK(V26),"",INDEX(호기!$A$1:$B$657,MATCH('생산계획(잉크)'!B478,호기!$A$1:$A$657,0),2)) | X26: =T26+V26-INDEX(표5[#All],MATCH(B26,표5[[#All],[잉크]],0),5) -> 0 | Y26: =IFERROR(X26/INDEX(표5[#All],MATCH(B26,표5[[#All],[잉크]],0),17),"") | AA26: =IF(ISBLANK(Z26),"",INDEX(호기!$A$1:$B$657,MATCH('생산계획(잉크)'!B478,호기!$A$1:$A$657,0),2)) | AB26: =X26+Z26-INDEX(표5[#All],MATCH(B26,표5[[#All],[잉크]],0),5) -> 0 | AC26: =IFERROR(AB26/INDEX(표5[#All],MATCH(B26,표5[[#All],[잉크]],0),20),"")
B27: BREMEN | D27: =IFERROR(C27/INDEX(표5[#All],MATCH(B27,표5[[#All],[잉크]],0),2),"") | E27: =$C27-INDEX(표5[#All],MATCH(B27,표5[[#All],[잉크]],0),24) -> 0 | G27: =IF(ISBLANK(F27),"",INDEX(호기!$A$1:$B$657,MATCH('생산계획(잉크)'!B479,호기!$A$1:$A$657,0),2)) | H27: =C27+F27-INDEX(표5[#All],MATCH(B27,표5[[#All],[잉크]],0),2) -> 0 | I27: =IFERROR(H27/INDEX(표5[#All],MATCH(B27,표5[[#All],[잉크]],0),5),"") | K27: =IF(ISBLANK(J27),"",INDEX(호기!$A$1:$B$657,MATCH('생산계획(잉크)'!B479,호기!$A$1:$A$657,0),2)) | L27: =H27+J27-INDEX(표5[#All],MATCH(B27,표5[[#All],[잉크]],0),5) -> 0 | M27: =IFERROR(L27/INDEX(표5[#All],MATCH(B27,표5[[#All],[잉크]],0),8),"") | O27: =IF(ISBLANK(N27),"",INDEX(호기!$A$1:$B$657,MATCH('생산계획(잉크)'!B479,호기!$A$1:$A$657,0),2)) | P27: =L27+N27-INDEX(표5[#All],MATCH(B27,표5[[#All],[잉크]],0),5) -> 0 | Q27: =IFERROR(P27/INDEX(표5[#All],MATCH(B27,표5[[#All],[잉크]],0),11),"") | S27: =IF(ISBLANK(R27),"",INDEX(호기!$A$1:$B$657,MATCH('생산계획(잉크)'!B479,호기!$A$1:$A$657,0),2)) | T27: =P27+R27-INDEX(표5[#All],MATCH(B27,표5[[#All],[잉크]],0),5) -> 0 | U27: =IFERROR(T27/INDEX(표5[#All],MATCH(B27,표5[[#All],[잉크]],0),14),"") | W27: =IF(ISBLANK(V27),"",INDEX(호기!$A$1:$B$657,MATCH('생산계획(잉크)'!B479,호기!$A$1:$A$657,0),2)) | X27: =T27+V27-INDEX(표5[#All],MATCH(B27,표5[[#All],[잉크]],0),5) -> 0 | Y27: =IFERROR(X27/INDEX(표5[#All],MATCH(B27,표5[[#All],[잉크]],0),17),"") | AA27: =IF(ISBLANK(Z27),"",INDEX(호기!$A$1:$B$657,MATCH('생산계획(잉크)'!B479,호기!$A$1:$A$657,0),2)) | AB27: =X27+Z27-INDEX(표5[#All],MATCH(B27,표5[[#All],[잉크]],0),5) -> 0 | AC27: =IFERROR(AB27/INDEX(표5[#All],MATCH(B27,표5[[#All],[잉크]],0),20),"")
B28: MAINZ | D28: =IFERROR(C28/INDEX(표5[#All],MATCH(B28,표5[[#All],[잉크]],0),2),"") | E28: =$C28-INDEX(표5[#All],MATCH(B28,표5[[#All],[잉크]],0),24) -> 0 | G28: =IF(ISBLANK(F28),"",INDEX(호기!$A$1:$B$657,MATCH('생산계획(잉크)'!B480,호기!$A$1:$A$657,0),2)) | H28: =C28+F28-INDEX(표5[#All],MATCH(B28,표5[[#All],[잉크]],0),2) -> 0 | I28: =IFERROR(H28/INDEX(표5[#All],MATCH(B28,표5[[#All],[잉크]],0),5),"") | K28: =IF(ISBLANK(J28),"",INDEX(호기!$A$1:$B$657,MATCH('생산계획(잉크)'!B480,호기!$A$1:$A$657,0),2)) | L28: =H28+J28-INDEX(표5[#All],MATCH(B28,표5[[#All],[잉크]],0),5) -> 0 | M28: =IFERROR(L28/INDEX(표5[#All],MATCH(B28,표5[[#All],[잉크]],0),8),"") | O28: =IF(ISBLANK(N28),"",INDEX(호기!$A$1:$B$657,MATCH('생산계획(잉크)'!B480,호기!$A$1:$A$657,0),2)) | P28: =L28+N28-INDEX(표5[#All],MATCH(B28,표5[[#All],[잉크]],0),5) -> 0 | Q28: =IFERROR(P28/INDEX(표5[#All],MATCH(B28,표5[[#All],[잉크]],0),11),"") | S28: =IF(ISBLANK(R28),"",INDEX(호기!$A$1:$B$657,MATCH('생산계획(잉크)'!B480,호기!$A$1:$A$657,0),2)) | T28: =P28+R28-INDEX(표5[#All],MATCH(B28,표5[[#All],[잉크]],0),5) -> 0 | U28: =IFERROR(T28/INDEX(표5[#All],MATCH(B28,표5[[#All],[잉크]],0),14),"") | W28: =IF(ISBLANK(V28),"",INDEX(호기!$A$1:$B$657,MATCH('생산계획(잉크)'!B480,호기!$A$1:$A$657,0),2)) | X28: =T28+V28-INDEX(표5[#All],MATCH(B28,표5[[#All],[잉크]],0),5) -> 0 | Y28: =IFERROR(X28/INDEX(표5[#All],MATCH(B28,표5[[#All],[잉크]],0),17),"") | AA28: =IF(ISBLANK(Z28),"",INDEX(호기!$A$1:$B$657,MATCH('생산계획(잉크)'!B480,호기!$A$1:$A$657,0),2)) | AB28: =X28+Z28-INDEX(표5[#All],MATCH(B28,표5[[#All],[잉크]],0),5) -> 0 | AC28: =IFERROR(AB28/INDEX(표5[#All],MATCH(B28,표5[[#All],[잉크]],0),20),"")
... B52: YEE | D52: =IFERROR(C52/INDEX(표5[#All],MATCH(B52,표5[[#All],[잉크]],0),2),"") | E52: =$C52-INDEX(표5[#All],MATCH(B52,표5[[#All],[잉크]],0),24) -> 0 | G52: =IF(ISBLANK(F52),"",INDEX(호기!$A$1:$B$657,MATCH('생산계획(잉크)'!B504,호기!$A$1:$A$657,0),2)) | H52: =C52+F52-INDEX(표5[#All],MATCH(B52,표5[[#All],[잉크]],0),2) -> 0 | I52: =IFERROR(H52/INDEX(표5[#All],MATCH(B52,표5[[#All],[잉크]],0),5),"") | K52: =IF(ISBLANK(J52),"",INDEX(호기!$A$1:$B$657,MATCH('생산계획(잉크)'!B504,호기!$A$1:$A$657,0),2)) | L52: =H52+J52-INDEX(표5[#All],MATCH(B52,표5[[#All],[잉크]],0),5) -> 0 | M52: =IFERROR(L52/INDEX(표5[#All],MATCH(B52,표5[[#All],[잉크]],0),8),"") | O52: =IF(ISBLANK(N52),"",INDEX(호기!$A$1:$B$657,MATCH('생산계획(잉크)'!B504,호기!$A$1:$A$657,0),2)) | P52: =L52+N52-INDEX(표5[#All],MATCH(B52,표5[[#All],[잉크]],0),5) -> 0 | Q52: =IFERROR(P52/INDEX(표5[#All],MATCH(B52,표5[[#All],[잉크]],0),11),"") | S52: =IF(ISBLANK(R52),"",INDEX(호기!$A$1:$B$657,MATCH('생산계획(잉크)'!B504,호기!$A$1:$A$657,0),2)) | T52: =P52+R52-INDEX(표5[#All],MATCH(B52,표5[[#All],[잉크]],0),5) -> 0 | U52: =IFERROR(T52/INDEX(표5[#All],MATCH(B52,표5[[#All],[잉크]],0),14),"") | W52: =IF(ISBLANK(V52),"",INDEX(호기!$A$1:$B$657,MATCH('생산계획(잉크)'!B504,호기!$A$1:$A$657,0),2)) | X52: =T52+V52-INDEX(표5[#All],MATCH(B52,표5[[#All],[잉크]],0),5) -> 0 | Y52: =IFERROR(X52/INDEX(표5[#All],MATCH(B52,표5[[#All],[잉크]],0),17),"") | AA52: =IF(ISBLANK(Z52),"",INDEX(호기!$A$1:$B$657,MATCH('생산계획(잉크)'!B504,호기!$A$1:$A$657,0),2)) | AB52: =X52+Z52-INDEX(표5[#All],MATCH(B52,표5[[#All],[잉크]],0),5) -> 0 | AC52: =IFERROR(AB52/INDEX(표5[#All],MATCH(B52,표5[[#All],[잉크]],0),20),"")
B53: WOLVER | C53: 2 | D53: =IFERROR(C53/INDEX(표5[#All],MATCH(B53,표5[[#All],[잉크]],0),2),"") -> 1 | E53: =$C53-INDEX(표5[#All],MATCH(B53,표5[[#All],[잉크]],0),24) -> -4 | G53: =IF(ISBLANK(F53),"",INDEX(호기!$A$1:$B$657,MATCH('생산계획(잉크)'!B505,호기!$A$1:$A$657,0),2)) | H53: =C53+F53-INDEX(표5[#All],MATCH(B53,표5[[#All],[잉크]],0),2) -> 0 | I53: =IFERROR(H53/INDEX(표5[#All],MATCH(B53,표5[[#All],[잉크]],0),5),"") -> 0 | J53: 2 | K53: =IF(ISBLANK(J53),"",INDEX(호기!$A$1:$B$657,MATCH('생산계획(잉크)'!B505,호기!$A$1:$A$657,0),2)) -> 6호기 | L53: =H53+J53-INDEX(표5[#All],MATCH(B53,표5[[#All],[잉크]],0),5) -> 1 | M53: =IFERROR(L53/INDEX(표5[#All],MATCH(B53,표5[[#All],[잉크]],0),8),"") | O53: =IF(ISBLANK(N53),"",INDEX(호기!$A$1:$B$657,MATCH('생산계획(잉크)'!B505,호기!$A$1:$A$657,0),2)) | P53: =L53+N53-INDEX(표5[#All],MATCH(B53,표5[[#All],[잉크]],0),5) -> 0 | Q53: =IFERROR(P53/INDEX(표5[#All],MATCH(B53,표5[[#All],[잉크]],0),11),"") | S53: =IF(ISBLANK(R53),"",INDEX(호기!$A$1:$B$657,MATCH('생산계획(잉크)'!B505,호기!$A$1:$A$657,0),2)) | T53: =P53+R53-INDEX(표5[#All],MATCH(B53,표5[[#All],[잉크]],0),5) -> -1 | U53: =IFERROR(T53/INDEX(표5[#All],MATCH(B53,표5[[#All],[잉크]],0),14),"") | W53: =IF(ISBLANK(V53),"",INDEX(호기!$A$1:$B$657,MATCH('생산계획(잉크)'!B505,호기!$A$1:$A$657,0),2)) | X53: =T53+V53-INDEX(표5[#All],MATCH(B53,표5[[#All],[잉크]],0),5) -> -2 | Y53: =IFERROR(X53/INDEX(표5[#All],MATCH(B53,표5[[#All],[잉크]],0),17),"") | AA53: =IF(ISBLANK(Z53),"",INDEX(호기!$A$1:$B$657,MATCH('생산계획(잉크)'!B505,호기!$A$1:$A$657,0),2)) | AB53: =X53+Z53-INDEX(표5[#All],MATCH(B53,표5[[#All],[잉크]],0),5) -> -3 | AC53: =IFERROR(AB53/INDEX(표5[#All],MATCH(B53,표5[[#All],[잉크]],0),20),"")
B54: HAMPTON | D54: =IFERROR(C54/INDEX(표5[#All],MATCH(B54,표5[[#All],[잉크]],0),2),"") | E54: =$C54-INDEX(표5[#All],MATCH(B54,표5[[#All],[잉크]],0),24) -> 0 | G54: =IF(ISBLANK(F54),"",INDEX(호기!$A$1:$B$657,MATCH('생산계획(잉크)'!B506,호기!$A$1:$A$657,0),2)) | H54: =C54+F54-INDEX(표5[#All],MATCH(B54,표5[[#All],[잉크]],0),2) -> 0 | I54: =IFERROR(H54/INDEX(표5[#All],MATCH(B54,표5[[#All],[잉크]],0),5),"") | K54: =IF(ISBLANK(J54),"",INDEX(호기!$A$1:$B$657,MATCH('생산계획(잉크)'!B506,호기!$A$1:$A$657,0),2)) | L54: =H54+J54-INDEX(표5[#All],MATCH(B54,표5[[#All],[잉크]],0),5) -> 0 | M54: =IFERROR(L54/INDEX(표5[#All],MATCH(B54,표5[[#All],[잉크]],0),8),"") | O54: =IF(ISBLANK(N54),"",INDEX(호기!$A$1:$B$657,MATCH('생산계획(잉크)'!B506,호기!$A$1:$A$657,0),2)) | P54: =L54+N54-INDEX(표5[#All],MATCH(B54,표5[[#All],[잉크]],0),5) -> 0 | Q54: =IFERROR(P54/INDEX(표5[#All],MATCH(B54,표5[[#All],[잉크]],0),11),"") | S54: =IF(ISBLANK(R54),"",INDEX(호기!$A$1:$B$657,MATCH('생산계획(잉크)'!B506,호기!$A$1:$A$657,0),2)) | T54: =P54+R54-INDEX(표5[#All],MATCH(B54,표5[[#All],[잉크]],0),5) -> 0 | U54: =IFERROR(T54/INDEX(표5[#All],MATCH(B54,표5[[#All],[잉크]],0),14),"") | W54: =IF(ISBLANK(V54),"",INDEX(호기!$A$1:$B$657,MATCH('생산계획(잉크)'!B506,호기!$A$1:$A$657,0),2)) | X54: =T54+V54-INDEX(표5[#All],MATCH(B54,표5[[#All],[잉크]],0),5) -> 0 | Y54: =IFERROR(X54/INDEX(표5[#All],MATCH(B54,표5[[#All],[잉크]],0),17),"") | AA54: =IF(ISBLANK(Z54),"",INDEX(호기!$A$1:$B$657,MATCH('생산계획(잉크)'!B506,호기!$A$1:$A$657,0),2)) | AB54: =X54+Z54-INDEX(표5[#All],MATCH(B54,표5[[#All],[잉크]],0),5) -> 0 | AC54: =IFERROR(AB54/INDEX(표5[#All],MATCH(B54,표5[[#All],[잉크]],0),20),"")
B55: WONDERERS | C55: 1 | D55: =IFERROR(C55/INDEX(표5[#All],MATCH(B55,표5[[#All],[잉크]],0),2),"") -> 0.5 | E55: =$C55-INDEX(표5[#All],MATCH(B55,표5[[#All],[잉크]],0),24) -> -5 | F55: 2 | G55: =IF(ISBLANK(F55),"",INDEX(호기!$A$1:$B$657,MATCH('생산계획(잉크)'!B507,호기!$A$1:$A$657,0),2)) -> 3호기 | H55: =C55+F55-INDEX(표5[#All],MATCH(B55,표5[[#All],[잉크]],0),2) -> 1 | I55: =IFERROR(H55/INDEX(표5[#All],MATCH(B55,표5[[#All],[잉크]],0),5),"") -> 1 | K55: =IF(ISBLANK(J55),"",INDEX(호기!$A$1:$B$657,MATCH('생산계획(잉크)'!B507,호기!$A$1:$A$657,0),2)) | L55: =H55+J55-INDEX(표5[#All],MATCH(B55,표5[[#All],[잉크]],0),5) -> 0 | M55: =IFERROR(L55/INDEX(표5[#All],MATCH(B55,표5[[#All],[잉크]],0),8),"") | O55: =IF(ISBLANK(N55),"",INDEX(호기!$A$1:$B$657,MATCH('생산계획(잉크)'!B507,호기!$A$1:$A$657,0),2)) | P55: =L55+N55-INDEX(표5[#All],MATCH(B55,표5[[#All],[잉크]],0),5) -> -1 | Q55: =IFERROR(P55/INDEX(표5[#All],MATCH(B55,표5[[#All],[잉크]],0),11),"") | S55: =IF(ISBLANK(R55),"",INDEX(호기!$A$1:$B$657,MATCH('생산계획(잉크)'!B507,호기!$A$1:$A$657,0),2)) | T55: =P55+R55-INDEX(표5[#All],MATCH(B55,표5[[#All],[잉크]],0),5) -> -2 | U55: =IFERROR(T55/INDEX(표5[#All],MATCH(B55,표5[[#All],[잉크]],0),14),"") | W55: =IF(ISBLANK(V55),"",INDEX(호기!$A$1:$B$657,MATCH('생산계획(잉크)'!B507,호기!$A$1:$A$657,0),2)) | X55: =T55+V55-INDEX(표5[#All],MATCH(B55,표5[[#All],[잉크]],0),5) -> -3 | Y55: =IFERROR(X55/INDEX(표5[#All],MATCH(B55,표5[[#All],[잉크]],0),17),"") | AA55: =IF(ISBLANK(Z55),"",INDEX(호기!$A$1:$B$657,MATCH('생산계획(잉크)'!B507,호기!$A$1:$A$657,0),2)) | AB55: =X55+Z55-INDEX(표5[#All],MATCH(B55,표5[[#All],[잉크]],0),5) -> -4 | AC55: =IFERROR(AB55/INDEX(표5[#All],MATCH(B55,표5[[#All],[잉크]],0),20),"")
B56: MONACO | D56: =IFERROR(C56/INDEX(표5[#All],MATCH(B56,표5[[#All],[잉크]],0),2),"") | E56: =$C56-INDEX(표5[#All],MATCH(B56,표5[[#All],[잉크]],0),24) -> 0 | G56: =IF(ISBLANK(F56),"",INDEX(호기!$A$1:$B$657,MATCH('생산계획(잉크)'!B508,호기!$A$1:$A$657,0),2)) | H56: =C56+F56-INDEX(표5[#All],MATCH(B56,표5[[#All],[잉크]],0),2) -> 0 | I56: =IFERROR(H56/INDEX(표5[#All],MATCH(B56,표5[[#All],[잉크]],0),5),"") | K56: =IF(ISBLANK(J56),"",INDEX(호기!$A$1:$B$657,MATCH('생산계획(잉크)'!B508,호기!$A$1:$A$657,0),2)) | L56: =H56+J56-INDEX(표5[#All],MATCH(B56,표5[[#All],[잉크]],0),5) -> 0 | M56: =IFERROR(L56/INDEX(표5[#All],MATCH(B56,표5[[#All],[잉크]],0),8),"") | O56: =IF(ISBLANK(N56),"",INDEX(호기!$A$1:$B$657,MATCH('생산계획(잉크)'!B508,호기!$A$1:$A$657,0),2)) | P56: =L56+N56-INDEX(표5[#All],MATCH(B56,표5[[#All],[잉크]],0),5) -> 0 | Q56: =IFERROR(P56/INDEX(표5[#All],MATCH(B56,표5[[#All],[잉크]],0),11),"") | S56: =IF(ISBLANK(R56),"",INDEX(호기!$A$1:$B$657,MATCH('생산계획(잉크)'!B508,호기!$A$1:$A$657,0),2)) | T56: =P56+R56-INDEX(표5[#All],MATCH(B56,표5[[#All],[잉크]],0),5) -> 0 | U56: =IFERROR(T56/INDEX(표5[#All],MATCH(B56,표5[[#All],[잉크]],0),14),"") | W56: =IF(ISBLANK(V56),"",INDEX(호기!$A$1:$B$657,MATCH('생산계획(잉크)'!B508,호기!$A$1:$A$657,0),2)) | X56: =T56+V56-INDEX(표5[#All],MATCH(B56,표5[[#All],[잉크]],0),5) -> 0 | Y56: =IFERROR(X56/INDEX(표5[#All],MATCH(B56,표5[[#All],[잉크]],0),17),"") | AA56: =IF(ISBLANK(Z56),"",INDEX(호기!$A$1:$B$657,MATCH('생산계획(잉크)'!B508,호기!$A$1:$A$657,0),2)) | AB56: =X56+Z56-INDEX(표5[#All],MATCH(B56,표5[[#All],[잉크]],0),5) -> 0 | AC56: =IFERROR(AB56/INDEX(표5[#All],MATCH(B56,표5[[#All],[잉크]],0),20),"")
B57: MARSEILLE | D57: =IFERROR(C57/INDEX(표5[#All],MATCH(B57,표5[[#All],[잉크]],0),2),"") | E57: =$C57-INDEX(표5[#All],MATCH(B57,표5[[#All],[잉크]],0),24) -> 0 | G57: =IF(ISBLANK(F57),"",INDEX(호기!$A$1:$B$657,MATCH('생산계획(잉크)'!B509,호기!$A$1:$A$657,0),2)) | H57: =C57+F57-INDEX(표5[#All],MATCH(B57,표5[[#All],[잉크]],0),2) -> 0 | I57: =IFERROR(H57/INDEX(표5[#All],MATCH(B57,표5[[#All],[잉크]],0),5),"") | K57: =IF(ISBLANK(J57),"",INDEX(호기!$A$1:$B$657,MATCH('생산계획(잉크)'!B509,호기!$A$1:$A$657,0),2)) | L57: =H57+J57-INDEX(표5[#All],MATCH(B57,표5[[#All],[잉크]],0),5) -> 0 | M57: =IFERROR(L57/INDEX(표5[#All],MATCH(B57,표5[[#All],[잉크]],0),8),"") | O57: =IF(ISBLANK(N57),"",INDEX(호기!$A$1:$B$657,MATCH('생산계획(잉크)'!B509,호기!$A$1:$A$657,0),2)) | P57: =L57+N57-INDEX(표5[#All],MATCH(B57,표5[[#All],[잉크]],0),5) -> 0 | Q57: =IFERROR(P57/INDEX(표5[#All],MATCH(B57,표5[[#All],[잉크]],0),11),"") | S57: =IF(ISBLANK(R57),"",INDEX(호기!$A$1:$B$657,MATCH('생산계획(잉크)'!B509,호기!$A$1:$A$657,0),2)) | T57: =P57+R57-INDEX(표5[#All],MATCH(B57,표5[[#All],[잉크]],0),5) -> 0 | U57: =IFERROR(T57/INDEX(표5[#All],MATCH(B57,표5[[#All],[잉크]],0),14),"") | W57: =IF(ISBLANK(V57),"",INDEX(호기!$A$1:$B$657,MATCH('생산계획(잉크)'!B509,호기!$A$1:$A$657,0),2)) | X57: =T57+V57-INDEX(표5[#All],MATCH(B57,표5[[#All],[잉크]],0),5) -> 0 | Y57: =IFERROR(X57/INDEX(표5[#All],MATCH(B57,표5[[#All],[잉크]],0),17),"") | AA57: =IF(ISBLANK(Z57),"",INDEX(호기!$A$1:$B$657,MATCH('생산계획(잉크)'!B509,호기!$A$1:$A$657,0),2)) | AB57: =X57+Z57-INDEX(표5[#All],MATCH(B57,표5[[#All],[잉크]],0),5) -> 0 | AC57: =IFERROR(AB57/INDEX(표5[#All],MATCH(B57,표5[[#All],[잉크]],0),20),"")
B58: LILLE | D58: =IFERROR(C58/INDEX(표5[#All],MATCH(B58,표5[[#All],[잉크]],0),2),"") | E58: =$C58-INDEX(표5[#All],MATCH(B58,표5[[#All],[잉크]],0),24) -> 0 | G58: =IF(ISBLANK(F58),"",INDEX(호기!$A$1:$B$657,MATCH('생산계획(잉크)'!B510,호기!$A$1:$A$657,0),2)) | H58: =C58+F58-INDEX(표5[#All],MATCH(B58,표5[[#All],[잉크]],0),2) -> 0 | I58: =IFERROR(H58/INDEX(표5[#All],MATCH(B58,표5[[#All],[잉크]],0),5),"") | K58: =IF(ISBLANK(J58),"",INDEX(호기!$A$1:$B$657,MATCH('생산계획(잉크)'!B510,호기!$A$1:$A$657,0),2)) | L58: =H58+J58-INDEX(표5[#All],MATCH(B58,표5[[#All],[잉크]],0),5) -> 0 | M58: =IFERROR(L58/INDEX(표5[#All],MATCH(B58,표5[[#All],[잉크]],0),8),"") | O58: =IF(ISBLANK(N58),"",INDEX(호기!$A$1:$B$657,MATCH('생산계획(잉크)'!B510,호기!$A$1:$A$657,0),2)) | P58: =L58+N58-INDEX(표5[#All],MATCH(B58,표5[[#All],[잉크]],0),5) -> 0 | Q58: =IFERROR(P58/INDEX(표5[#All],MATCH(B58,표5[[#All],[잉크]],0),11),"") | S58: =IF(ISBLANK(R58),"",INDEX(호기!$A$1:$B$657,MATCH('생산계획(잉크)'!B510,호기!$A$1:$A$657,0),2)) | T58: =P58+R58-INDEX(표5[#All],MATCH(B58,표5[[#All],[잉크]],0),5) -> 0 | U58: =IFERROR(T58/INDEX(표5[#All],MATCH(B58,표5[[#All],[잉크]],0),14),"") | W58: =IF(ISBLANK(V58),"",INDEX(호기!$A$1:$B$657,MATCH('생산계획(잉크)'!B510,호기!$A$1:$A$657,0),2)) | X58: =T58+V58-INDEX(표5[#All],MATCH(B58,표5[[#All],[잉크]],0),5) -> 0 | Y58: =IFERROR(X58/INDEX(표5[#All],MATCH(B58,표5[[#All],[잉크]],0),17),"") | AA58: =IF(ISBLANK(Z58),"",INDEX(호기!$A$1:$B$657,MATCH('생산계획(잉크)'!B510,호기!$A$1:$A$657,0),2)) | AB58: =X58+Z58-INDEX(표5[#All],MATCH(B58,표5[[#All],[잉크]],0),5) -> 0 | AC58: =IFERROR(AB58/INDEX(표5[#All],MATCH(B58,표5[[#All],[잉크]],0),20),"")
B59: KAHVE | D59: =IFERROR(C59/INDEX(표5[#All],MATCH(B59,표5[[#All],[잉크]],0),2),"") | E59: =$C59-INDEX(표5[#All],MATCH(B59,표5[[#All],[잉크]],0),24) -> 0 | G59: =IF(ISBLANK(F59),"",INDEX(호기!$A$1:$B$657,MATCH('생산계획(잉크)'!B511,호기!$A$1:$A$657,0),2)) | H59: =C59+F59-INDEX(표5[#All],MATCH(B59,표5[[#All],[잉크]],0),2) -> 0 | I59: =IFERROR(H59/INDEX(표5[#All],MATCH(B59,표5[[#All],[잉크]],0),5),"") | K59: =IF(ISBLANK(J59),"",INDEX(호기!$A$1:$B$657,MATCH('생산계획(잉크)'!B511,호기!$A$1:$A$657,0),2)) | L59: =H59+J59-INDEX(표5[#All],MATCH(B59,표5[[#All],[잉크]],0),5) -> 0 | M59: =IFERROR(L59/INDEX(표5[#All],MATCH(B59,표5[[#All],[잉크]],0),8),"") | O59: =IF(ISBLANK(N59),"",INDEX(호기!$A$1:$B$657,MATCH('생산계획(잉크)'!B511,호기!$A$1:$A$657,0),2)) | P59: =L59+N59-INDEX(표5[#All],MATCH(B59,표5[[#All],[잉크]],0),5) -> 0 | Q59: =IFERROR(P59/INDEX(표5[#All],MATCH(B59,표5[[#All],[잉크]],0),11),"") | S59: =IF(ISBLANK(R59),"",INDEX(호기!$A$1:$B$657,MATCH('생산계획(잉크)'!B511,호기!$A$1:$A$657,0),2)) | T59: =P59+R59-INDEX(표5[#All],MATCH(B59,표5[[#All],[잉크]],0),5) -> 0 | U59: =IFERROR(T59/INDEX(표5[#All],MATCH(B59,표5[[#All],[잉크]],0),14),"") | W59: =IF(ISBLANK(V59),"",INDEX(호기!$A$1:$B$657,MATCH('생산계획(잉크)'!B511,호기!$A$1:$A$657,0),2)) | X59: =T59+V59-INDEX(표5[#All],MATCH(B59,표5[[#All],[잉크]],0),5) -> 0 | Y59: =IFERROR(X59/INDEX(표5[#All],MATCH(B59,표5[[#All],[잉크]],0),17),"") | AA59: =IF(ISBLANK(Z59),"",INDEX(호기!$A$1:$B$657,MATCH('생산계획(잉크)'!B511,호기!$A$1:$A$657,0),2)) | AB59: =X59+Z59-INDEX(표5[#All],MATCH(B59,표5[[#All],[잉크]],0),5) -> 0 | AC59: =IFERROR(AB59/INDEX(표5[#All],MATCH(B59,표5[[#All],[잉크]],0),20),"")
B60: UVPOMME | D60: =IFERROR(C60/INDEX(표5[#All],MATCH(B60,표5[[#All],[잉크]],0),2),"") | E60: =$C60-INDEX(표5[#All],MATCH(B60,표5[[#All],[잉크]],0),24) -> 0 | G60: =IF(ISBLANK(F60),"",INDEX(호기!$A$1:$B$657,MATCH('생산계획(잉크)'!B512,호기!$A$1:$A$657,0),2)) | H60: =C60+F60-INDEX(표5[#All],MATCH(B60,표5[[#All],[잉크]],0),2) -> 0 | I60: =IFERROR(H60/INDEX(표5[#All],MATCH(B60,표5[[#All],[잉크]],0),5),"") | K60: =IF(ISBLANK(J60),"",INDEX(호기!$A$1:$B$657,MATCH('생산계획(잉크)'!B512,호기!$A$1:$A$657,0),2)) | L60: =H60+J60-INDEX(표5[#All],MATCH(B60,표5[[#All],[잉크]],0),5) -> 0 | M60: =IFERROR(L60/INDEX(표5[#All],MATCH(B60,표5[[#All],[잉크]],0),8),"") | O60: =IF(ISBLANK(N60),"",INDEX(호기!$A$1:$B$657,MATCH('생산계획(잉크)'!B512,호기!$A$1:$A$657,0),2)) | P60: =L60+N60-INDEX(표5[#All],MATCH(B60,표5[[#All],[잉크]],0),5) -> 0 | Q60: =IFERROR(P60/INDEX(표5[#All],MATCH(B60,표5[[#All],[잉크]],0),11),"") | S60: =IF(ISBLANK(R60),"",INDEX(호기!$A$1:$B$657,MATCH('생산계획(잉크)'!B512,호기!$A$1:$A$657,0),2)) | T60: =P60+R60-INDEX(표5[#All],MATCH(B60,표5[[#All],[잉크]],0),5) -> 0 | U60: =IFERROR(T60/INDEX(표5[#All],MATCH(B60,표5[[#All],[잉크]],0),14),"") | W60: =IF(ISBLANK(V60),"",INDEX(호기!$A$1:$B$657,MATCH('생산계획(잉크)'!B512,호기!$A$1:$A$657,0),2)) | X60: =T60+V60-INDEX(표5[#All],MATCH(B60,표5[[#All],[잉크]],0),5) -> 0 | Y60: =IFERROR(X60/INDEX(표5[#All],MATCH(B60,표5[[#All],[잉크]],0),17),"") | AA60: =IF(ISBLANK(Z60),"",INDEX(호기!$A$1:$B$657,MATCH('생산계획(잉크)'!B512,호기!$A$1:$A$657,0),2)) | AB60: =X60+Z60-INDEX(표5[#All],MATCH(B60,표5[[#All],[잉크]],0),5) -> 0 | AC60: =IFERROR(AB60/INDEX(표5[#All],MATCH(B60,표5[[#All],[잉크]],0),20),"")
B61: FRIAR | D61: =IFERROR(C61/INDEX(표5[#All],MATCH(B61,표5[[#All],[잉크]],0),2),"") | E61: =$C61-INDEX(표5[#All],MATCH(B61,표5[[#All],[잉크]],0),24) -> 0 | G61: =IF(ISBLANK(F61),"",INDEX(호기!$A$1:$B$657,MATCH('생산계획(잉크)'!B513,호기!$A$1:$A$657,0),2)) | H61: =C61+F61-INDEX(표5[#All],MATCH(B61,표5[[#All],[잉크]],0),2) -> 0 | I61: =IFERROR(H61/INDEX(표5[#All],MATCH(B61,표5[[#All],[잉크]],0),5),"") | K61: =IF(ISBLANK(J61),"",INDEX(호기!$A$1:$B$657,MATCH('생산계획(잉크)'!B513,호기!$A$1:$A$657,0),2)) | L61: =H61+J61-INDEX(표5[#All],MATCH(B61,표5[[#All],[잉크]],0),5) -> 0 | M61: =IFERROR(L61/INDEX(표5[#All],MATCH(B61,표5[[#All],[잉크]],0),8),"") | O61: =IF(ISBLANK(N61),"",INDEX(호기!$A$1:$B$657,MATCH('생산계획(잉크)'!B513,호기!$A$1:$A$657,0),2)) | P61: =L61+N61-INDEX(표5[#All],MATCH(B61,표5[[#All],[잉크]],0),5) -> 0 | Q61: =IFERROR(P61/INDEX(표5[#All],MATCH(B61,표5[[#All],[잉크]],0),11),"") | S61: =IF(ISBLANK(R61),"",INDEX(호기!$A$1:$B$657,MATCH('생산계획(잉크)'!B513,호기!$A$1:$A$657,0),2)) | T61: =P61+R61-INDEX(표5[#All],MATCH(B61,표5[[#All],[잉크]],0),5) -> 0 | U61: =IFERROR(T61/INDEX(표5[#All],MATCH(B61,표5[[#All],[잉크]],0),14),"") | W61: =IF(ISBLANK(V61),"",INDEX(호기!$A$1:$B$657,MATCH('생산계획(잉크)'!B513,호기!$A$1:$A$657,0),2)) | X61: =T61+V61-INDEX(표5[#All],MATCH(B61,표5[[#All],[잉크]],0),5) -> 0 | Y61: =IFERROR(X61/INDEX(표5[#All],MATCH(B61,표5[[#All],[잉크]],0),17),"") | AA61: =IF(ISBLANK(Z61),"",INDEX(호기!$A$1:$B$657,MATCH('생산계획(잉크)'!B513,호기!$A$1:$A$657,0),2)) | AB61: =X61+Z61-INDEX(표5[#All],MATCH(B61,표5[[#All],[잉크]],0),5) -> 0 | AC61: =IFERROR(AB61/INDEX(표5[#All],MATCH(B61,표5[[#All],[잉크]],0),20),"")
B62: INCA | D62: =IFERROR(C62/INDEX(표5[#All],MATCH(B62,표5[[#All],[잉크]],0),2),"") | E62: =$C62-INDEX(표5[#All],MATCH(B62,표5[[#All],[잉크]],0),24) -> 0 | G62: =IF(ISBLANK(F62),"",INDEX(호기!$A$1:$B$657,MATCH('생산계획(잉크)'!B514,호기!$A$1:$A$657,0),2)) | H62: =C62+F62-INDEX(표5[#All],MATCH(B62,표5[[#All],[잉크]],0),2) -> 0 | I62: =IFERROR(H62/INDEX(표5[#All],MATCH(B62,표5[[#All],[잉크]],0),5),"") | K62: =IF(ISBLANK(J62),"",INDEX(호기!$A$1:$B$657,MATCH('생산계획(잉크)'!B514,호기!$A$1:$A$657,0),2)) | L62: =H62+J62-INDEX(표5[#All],MATCH(B62,표5[[#All],[잉크]],0),5) -> 0 | M62: =IFERROR(L62/INDEX(표5[#All],MATCH(B62,표5[[#All],[잉크]],0),8),"") | O62: =IF(ISBLANK(N62),"",INDEX(호기!$A$1:$B$657,MATCH('생산계획(잉크)'!B514,호기!$A$1:$A$657,0),2)) | P62: =L62+N62-INDEX(표5[#All],MATCH(B62,표5[[#All],[잉크]],0),5) -> 0 | Q62: =IFERROR(P62/INDEX(표5[#All],MATCH(B62,표5[[#All],[잉크]],0),11),"") | S62: =IF(ISBLANK(R62),"",INDEX(호기!$A$1:$B$657,MATCH('생산계획(잉크)'!B514,호기!$A$1:$A$657,0),2)) | T62: =P62+R62-INDEX(표5[#All],MATCH(B62,표5[[#All],[잉크]],0),5) -> 0 | U62: =IFERROR(T62/INDEX(표5[#All],MATCH(B62,표5[[#All],[잉크]],0),14),"") | W62: =IF(ISBLANK(V62),"",INDEX(호기!$A$1:$B$657,MATCH('생산계획(잉크)'!B514,호기!$A$1:$A$657,0),2)) | X62: =T62+V62-INDEX(표5[#All],MATCH(B62,표5[[#All],[잉크]],0),5) -> 0 | Y62: =IFERROR(X62/INDEX(표5[#All],MATCH(B62,표5[[#All],[잉크]],0),17),"") | AA62: =IF(ISBLANK(Z62),"",INDEX(호기!$A$1:$B$657,MATCH('생산계획(잉크)'!B514,호기!$A$1:$A$657,0),2)) | AB62: =X62+Z62-INDEX(표5[#All],MATCH(B62,표5[[#All],[잉크]],0),5) -> 0 | AC62: =IFERROR(AB62/INDEX(표5[#All],MATCH(B62,표5[[#All],[잉크]],0),20),"")
B63: MECCA | D63: =IFERROR(C63/INDEX(표5[#All],MATCH(B63,표5[[#All],[잉크]],0),2),"") | E63: =$C63-INDEX(표5[#All],MATCH(B63,표5[[#All],[잉크]],0),24) -> 0 | G63: =IF(ISBLANK(F63),"",INDEX(호기!$A$1:$B$657,MATCH('생산계획(잉크)'!B515,호기!$A$1:$A$657,0),2)) | H63: =C63+F63-INDEX(표5[#All],MATCH(B63,표5[[#All],[잉크]],0),2) -> 0 | I63: =IFERROR(H63/INDEX(표5[#All],MATCH(B63,표5[[#All],[잉크]],0),5),"") | K63: =IF(ISBLANK(J63),"",INDEX(호기!$A$1:$B$657,MATCH('생산계획(잉크)'!B515,호기!$A$1:$A$657,0),2)) | L63: =H63+J63-INDEX(표5[#All],MATCH(B63,표5[[#All],[잉크]],0),5) -> 0 | M63: =IFERROR(L63/INDEX(표5[#All],MATCH(B63,표5[[#All],[잉크]],0),8),"") | O63: =IF(ISBLANK(N63),"",INDEX(호기!$A$1:$B$657,MATCH('생산계획(잉크)'!B515,호기!$A$1:$A$657,0),2)) | P63: =L63+N63-INDEX(표5[#All],MATCH(B63,표5[[#All],[잉크]],0),5) -> 0 | Q63: =IFERROR(P63/INDEX(표5[#All],MATCH(B63,표5[[#All],[잉크]],0),11),"") | S63: =IF(ISBLANK(R63),"",INDEX(호기!$A$1:$B$657,MATCH('생산계획(잉크)'!B515,호기!$A$1:$A$657,0),2)) | T63: =P63+R63-INDEX(표5[#All],MATCH(B63,표5[[#All],[잉크]],0),5) -> 0 | U63: =IFERROR(T63/INDEX(표5[#All],MATCH(B63,표5[[#All],[잉크]],0),14),"") | W63: =IF(ISBLANK(V63),"",INDEX(호기!$A$1:$B$657,MATCH('생산계획(잉크)'!B515,호기!$A$1:$A$657,0),2)) | X63: =T63+V63-INDEX(표5[#All],MATCH(B63,표5[[#All],[잉크]],0),5) -> 0 | Y63: =IFERROR(X63/INDEX(표5[#All],MATCH(B63,표5[[#All],[잉크]],0),17),"") | AA63: =IF(ISBLANK(Z63),"",INDEX(호기!$A$1:$B$657,MATCH('생산계획(잉크)'!B515,호기!$A$1:$A$657,0),2)) | AB63: =X63+Z63-INDEX(표5[#All],MATCH(B63,표5[[#All],[잉크]],0),5) -> 0 | AC63: =IFERROR(AB63/INDEX(표5[#All],MATCH(B63,표5[[#All],[잉크]],0),20),"")
